Workbook

Sheet Main
B1: Abusing Fantasy Draft Rankings - 2025
B3: Finding Values | H3: Contact for questions: | J3: Extras
B4: During drafts, the rankings you see will automatically be sorted by the host site's draft rankings. In each tab, the colored tabs will portray how much higher or lower the draft site has the player ranked. Typically if they're ranked higher on the site, they're going to be drafted higher, and vice versa if they are ranked lower - the site ranks influence the draft. These pages will help you during the draft to figure out if it's too early to take a player based on FantasyPros rankings. | H4: Twitter | J4: Newsletter
H5: Reddit
B7: Color Codes | H7: Jump To Page | J7: All Draft Comparisons
B8: Good Value (Blue) | D8: QB | H8: ESPN Standard | J8: Standard
B9: Poor Value (Orange) | D9: RB | H9: ESPN .5PPR | J9: Half PPR
D10: WR | H10: ESPN PPR | J10: PPR
D11: TE | H11: Yahoo Standard
H12: Yahoo .5PPR | J12: Date of Last Update
B13: Extras | H13: Yahoo PPR | J13: 45841
B14: - Insert an x to the left of player names to cross that player off, marking them as drafted. | H14: Sleeper Standard
B15: - In order to edit the sheet, make a copy by going to File > Make a copy | H15: Sleeper .5PPR | J15: Make a Copy
H16: Sleeper PPR | J16: Copy
B17: Sources | H17: NFL
B18: - ESPN draft rankings come from their mock drafts | H18: CBS PPR
B19: - Yahoo x-rank draft rankings come from their mock drafts | H19: Fleaflicker
B20: - Sleeper draft rankings come from their public ADP sheets
B22: New in 2025
B23: Landmine Score: A 0-10 scale rating how risky a player is in your draft room, based on how much earlier they’re ranked on your platform versus expert consensus. 0 = Great value 10 = Landmine, avoid

Sheet Team
B1: Ben | C1: Kev | D1: Hugo | E1: Iack | F1: Thomas | G1: Phil | H1: JF | I1: Jerome | J1: Web | K1: Fred
A2: 1 | B2: =IFERROR(__xludf.DUMMYFUNCTION("IFERROR(INDEX(FILTER(Keeper!$B:$B, Keeper!$A:$A=B$1), ROW(A1)), """")"),"Malik Nabers") | C2: =IFERROR(__xludf.DUMMYFUNCTION("IFERROR(INDEX(FILTER(Keeper!$B:$B, Keeper!$A:$A=C$1), ROW(B1)), """")"),"Jahmyr Gibbs") | D2: =IFERROR(__xludf.DUMMYFUNCTION("IFERROR(INDEX(FILTER(Keeper!$B:$B, Keeper!$A:$A=D$1), ROW(C1)), """")"),"Chase Brown") | E2: =IFERROR(__xludf.DUMMYFUNCTION("IFERROR(INDEX(FILTER(Keeper!$B:$B, Keeper!$A:$A=E$1), ROW(D1)), """")"),"De'Von Achane") | F2: =IFERROR(__xludf.DUMMYFUNCTION("IFERROR(INDEX(FILTER(Keeper!$B:$B, Keeper!$A:$A=F$1), ROW(E1)), """")"),"Christian McCaffrey") | G2: =IFERROR(__xludf.DUMMYFUNCTION("IFERROR(INDEX(FILTER(Keeper!$B:$B, Keeper!$A:$A=G$1), ROW(F1)), """")"),"Drake Maye") | H2: =IFERROR(__xludf.DUMMYFUNCTION("IFERROR(INDEX(FILTER(Keeper!$B:$B, Keeper!$A:$A=H$1), ROW(G1)), """")"),"Garrett Wilson") | I2: =IFERROR(__xludf.DUMMYFUNCTION("IFERROR(INDEX(FILTER(Keeper!$B:$B, Keeper!$A:$A=I$1), ROW(H1)), """")"),"Ja'Marr Chase") | J2: =IFERROR(__xludf.DUMMYFUNCTION("IFERROR(INDEX(FILTER(Keeper!$B:$B, Keeper!$A:$A=J$1), ROW(I1)), """")"),"Omarion Hampton") | K2: =IFERROR(__xludf.DUMMYFUNCTION("IFERROR(INDEX(FILTER(Keeper!$B:$B, Keeper!$A:$A=K$1), ROW(J1)), """")"),"Drake London")
A3: 2 | B3: =IFERROR(__xludf.DUMMYFUNCTION("IFERROR(INDEX(FILTER(Keeper!$B:$B, Keeper!$A:$A=B$1), ROW(A2)), """")"),"Brock Bowers") | C3: =IFERROR(__xludf.DUMMYFUNCTION("IFERROR(INDEX(FILTER(Keeper!$B:$B, Keeper!$A:$A=C$1), ROW(B2)), """")"),"Josh Jacobs") | D3: =IFERROR(__xludf.DUMMYFUNCTION("IFERROR(INDEX(FILTER(Keeper!$B:$B, Keeper!$A:$A=D$1), ROW(C2)), """")"),"Justin Jefferson") | E3: =IFERROR(__xludf.DUMMYFUNCTION("IFERROR(INDEX(FILTER(Keeper!$B:$B, Keeper!$A:$A=E$1), ROW(D2)), """")"),"Ashton Jeanty") | F3: =IFERROR(__xludf.DUMMYFUNCTION("IFERROR(INDEX(FILTER(Keeper!$B:$B, Keeper!$A:$A=F$1), ROW(E2)), """")"),"Jonathan Taylor") | G3: =IFERROR(__xludf.DUMMYFUNCTION("IFERROR(INDEX(FILTER(Keeper!$B:$B, Keeper!$A:$A=G$1), ROW(F2)), """")"),"Saquon Barkley") | H3: =IFERROR(__xludf.DUMMYFUNCTION("IFERROR(INDEX(FILTER(Keeper!$B:$B, Keeper!$A:$A=H$1), ROW(G2)), """")"),"Kyren Williams") | I3: =IFERROR(__xludf.DUMMYFUNCTION("IFERROR(INDEX(FILTER(Keeper!$B:$B, Keeper!$A:$A=I$1), ROW(H2)), """")"),"Chris Olave") | J3: =IFERROR(__xludf.DUMMYFUNCTION("IFERROR(INDEX(FILTER(Keeper!$B:$B, Keeper!$A:$A=J$1), ROW(I2)), """")"),"Bijan Robinson") | K3: =IFERROR(__xludf.DUMMYFUNCTION("IFERROR(INDEX(FILTER(Keeper!$B:$B, Keeper!$A:$A=K$1), ROW(J2)), """")"),"Trey McBride")
A4: 3 | B4: =IFERROR(__xludf.DUMMYFUNCTION("IFERROR(INDEX(FILTER(Keeper!$B:$B, Keeper!$A:$A=B$1), ROW(A3)), """")"),"CeeDee Lamb") | C4: =IFERROR(__xludf.DUMMYFUNCTION("IFERROR(INDEX(FILTER(Keeper!$B:$B, Keeper!$A:$A=C$1), ROW(B3)), """")"),"Rashee Rice") | D4: =IFERROR(__xludf.DUMMYFUNCTION("IFERROR(INDEX(FILTER(Keeper!$B:$B, Keeper!$A:$A=D$1), ROW(C3)), """")"),"George Pickens") | E4: =IFERROR(__xludf.DUMMYFUNCTION("IFERROR(INDEX(FILTER(Keeper!$B:$B, Keeper!$A:$A=E$1), ROW(D3)), """")"),"Amon-Ra St. Brown") | F4: =IFERROR(__xludf.DUMMYFUNCTION("IFERROR(INDEX(FILTER(Keeper!$B:$B, Keeper!$A:$A=F$1), ROW(E3)), """")"),"Puka Nacua") | G4: =IFERROR(__xludf.DUMMYFUNCTION("IFERROR(INDEX(FILTER(Keeper!$B:$B, Keeper!$A:$A=G$1), ROW(F3)), """")"),"Jaxon Smith-Njigba") | H4: =IFERROR(__xludf.DUMMYFUNCTION("IFERROR(INDEX(FILTER(Keeper!$B:$B, Keeper!$A:$A=H$1), ROW(G3)), """")"),"James Cook III") | I4: =IFERROR(__xludf.DUMMYFUNCTION("IFERROR(INDEX(FILTER(Keeper!$B:$B, Keeper!$A:$A=I$1), ROW(H3)), """")"),"Josh Allen") | J4: =IFERROR(__xludf.DUMMYFUNCTION("IFERROR(INDEX(FILTER(Keeper!$B:$B, Keeper!$A:$A=J$1), ROW(I3)), """")"),"Nico Collins") | K4: =IFERROR(__xludf.DUMMYFUNCTION("IFERROR(INDEX(FILTER(Keeper!$B:$B, Keeper!$A:$A=K$1), ROW(J3)), """")"),"Tetairoa McMillan")
A5: 4 | B5: =IFERROR(__xludf.DUMMYFUNCTION("IFERROR(INDEX(FILTER(Draft!$B$2:$B1000, Draft!$A$2:$A1000=B$1), ROW(A1)), """")"),"Travis Etienne Jr.") | C5: =IFERROR(__xludf.DUMMYFUNCTION("IFERROR(INDEX(FILTER(Draft!$B$2:$B1000, Draft!$A$2:$A1000=C$1), ROW(B1)), """")"),"Lamar Jackson") | D5: =IFERROR(__xludf.DUMMYFUNCTION("IFERROR(INDEX(FILTER(Draft!$B$2:$B1000, Draft!$A$2:$A1000=D$1), ROW(C1)), """")"),"Derrick Henry") | E5: =IFERROR(__xludf.DUMMYFUNCTION("IFERROR(INDEX(FILTER(Draft!$B$2:$B1000, Draft!$A$2:$A1000=E$1), ROW(D1)), """")"),"Zay Flowers") | F5: =IFERROR(__xludf.DUMMYFUNCTION("IFERROR(INDEX(FILTER(Draft!$B$2:$B1000, Draft!$A$2:$A1000=F$1), ROW(E1)), """")"),"Tucker Kraft") | G5: =IFERROR(__xludf.DUMMYFUNCTION("IFERROR(INDEX(FILTER(Draft!$B$2:$B1000, Draft!$A$2:$A1000=G$1), ROW(F1)), """")"),"Javonte Williams") | H5: =IFERROR(__xludf.DUMMYFUNCTION("IFERROR(INDEX(FILTER(Draft!$B$2:$B1000, Draft!$A$2:$A1000=H$1), ROW(G1)), """")"),"Colston Loveland") | I5: =IFERROR(__xludf.DUMMYFUNCTION("IFERROR(INDEX(FILTER(Draft!$B$2:$B1000, Draft!$A$2:$A1000=I$1), ROW(H1)), """")"),"") | J5: Jeremiyah Love | K5: =IFERROR(__xludf.DUMMYFUNCTION("IFERROR(INDEX(FILTER(Draft!$B$2:$B1000, Draft!$A$2:$A1000=K$1), ROW(J1)), """")"),"Tee Higgins")
A6: 5 | B6: =IFERROR(__xludf.DUMMYFUNCTION("IFERROR(INDEX(FILTER(Draft!$B$2:$B1000, Draft!$A$2:$A1000=B$1), ROW(A2)), """")"),"Ladd McConkey") | C6: =IFERROR(__xludf.DUMMYFUNCTION("IFERROR(INDEX(FILTER(Draft!$B$2:$B1000, Draft!$A$2:$A1000=C$1), ROW(B2)), """")"),"Joe Burrow") | D6: =IFERROR(__xludf.DUMMYFUNCTION("IFERROR(INDEX(FILTER(Draft!$B$2:$B1000, Draft!$A$2:$A1000=D$1), ROW(C2)), """")"),"Jameson Williams") | E6: =IFERROR(__xludf.DUMMYFUNCTION("IFERROR(INDEX(FILTER(Draft!$B$2:$B1000, Draft!$A$2:$A1000=E$1), ROW(D2)), """")"),"Mike Evans") | F6: =IFERROR(__xludf.DUMMYFUNCTION("IFERROR(INDEX(FILTER(Draft!$B$2:$B1000, Draft!$A$2:$A1000=F$1), ROW(E2)), """")"),"D'Andre Swift") | G6: =IFERROR(__xludf.DUMMYFUNCTION("IFERROR(INDEX(FILTER(Draft!$B$2:$B1000, Draft!$A$2:$A1000=G$1), ROW(F2)), """")"),"Makai Lemon") | H6: =IFERROR(__xludf.DUMMYFUNCTION("IFERROR(INDEX(FILTER(Draft!$B$2:$B1000, Draft!$A$2:$A1000=H$1), ROW(G2)), """")"),"Emeka Egbuka") | I6: =IFERROR(__xludf.DUMMYFUNCTION("IFERROR(INDEX(FILTER(Draft!$B$2:$B1000, Draft!$A$2:$A1000=I$1), ROW(H2)), """")"),"") | J6: =IFERROR(__xludf.DUMMYFUNCTION("IFERROR(INDEX(FILTER(Draft!$B$2:$B1000, Draft!$A$2:$A1000=J$1), ROW(I2)), """")"),"Kenneth Walker III") | K6: =IFERROR(__xludf.DUMMYFUNCTION("IFERROR(INDEX(FILTER(Draft!$B$2:$B1000, Draft!$A$2:$A1000=K$1), ROW(J2)), """")"),"A.J. Brown")
A7: 6 | B7: =IFERROR(__xludf.DUMMYFUNCTION("IFERROR(INDEX(FILTER(Draft!$B$2:$B1000, Draft!$A$2:$A1000=B$1), ROW(A3)), """")"),"Terry McLaurin") | C7: =IFERROR(__xludf.DUMMYFUNCTION("IFERROR(INDEX(FILTER(Draft!$B$2:$B1000, Draft!$A$2:$A1000=C$1), ROW(B3)), """")"),"Bucky Irving") | D7: =IFERROR(__xludf.DUMMYFUNCTION("IFERROR(INDEX(FILTER(Draft!$B$2:$B1000, Draft!$A$2:$A1000=D$1), ROW(C3)), """")"),"Jalen Hurts") | E7: =IFERROR(__xludf.DUMMYFUNCTION("IFERROR(INDEX(FILTER(Draft!$B$2:$B1000, Draft!$A$2:$A1000=E$1), ROW(D3)), """")"),"Alec Pierce") | F7: =IFERROR(__xludf.DUMMYFUNCTION("IFERROR(INDEX(FILTER(Draft!$B$2:$B1000, Draft!$A$2:$A1000=F$1), ROW(E3)), """")"),"Jaylen Warren") | G7: =IFERROR(__xludf.DUMMYFUNCTION("IFERROR(INDEX(FILTER(Draft!$B$2:$B1000, Draft!$A$2:$A1000=G$1), ROW(F3)), """")"),"Caleb Williams") | H7: =IFERROR(__xludf.DUMMYFUNCTION("IFERROR(INDEX(FILTER(Draft!$B$2:$B1000, Draft!$A$2:$A1000=H$1), ROW(G3)), """")"),"DeVonta Smith") | I7: =IFERROR(__xludf.DUMMYFUNCTION("IFERROR(INDEX(FILTER(Draft!$B$2:$B1000, Draft!$A$2:$A1000=I$1), ROW(H3)), """")"),"") | J7: =IFERROR(__xludf.DUMMYFUNCTION("IFERROR(INDEX(FILTER(Draft!$B$2:$B1000, Draft!$A$2:$A1000=J$1), ROW(I3)), """")"),"Josh Jacobs") | K7: =IFERROR(__xludf.DUMMYFUNCTION("IFERROR(INDEX(FILTER(Draft!$B$2:$B1000, Draft!$A$2:$A1000=K$1), ROW(J3)), """")"),"Breece Hall")
A8: 7 | B8: =IFERROR(__xludf.DUMMYFUNCTION("IFERROR(INDEX(FILTER(Draft!$B$2:$B1000, Draft!$A$2:$A1000=B$1), ROW(A4)), """")"),"Christian Watson") | C8: =IFERROR(__xludf.DUMMYFUNCTION("IFERROR(INDEX(FILTER(Draft!$B$2:$B1000, Draft!$A$2:$A1000=C$1), ROW(B4)), """")"),"Jaylen Waddle") | D8: =IFERROR(__xludf.DUMMYFUNCTION("IFERROR(INDEX(FILTER(Draft!$B$2:$B1000, Draft!$A$2:$A1000=D$1), ROW(C4)), """")"),"DJ Moore") | E8: =IFERROR(__xludf.DUMMYFUNCTION("IFERROR(INDEX(FILTER(Draft!$B$2:$B1000, Draft!$A$2:$A1000=E$1), ROW(D4)), """")"),"Jaxson Dart") | F8: =IFERROR(__xludf.DUMMYFUNCTION("IFERROR(INDEX(FILTER(Draft!$B$2:$B1000, Draft!$A$2:$A1000=F$1), ROW(E4)), """")"),"") | G8: =IFERROR(__xludf.DUMMYFUNCTION("IFERROR(INDEX(FILTER(Draft!$B$2:$B1000, Draft!$A$2:$A1000=G$1), ROW(F4)), """")"),"") | H8: =IFERROR(__xludf.DUMMYFUNCTION("IFERROR(INDEX(FILTER(Draft!$B$2:$B1000, Draft!$A$2:$A1000=H$1), ROW(G4)), """")"),"Jordyn Tyson") | I8: =IFERROR(__xludf.DUMMYFUNCTION("IFERROR(INDEX(FILTER(Draft!$B$2:$B1000, Draft!$A$2:$A1000=I$1), ROW(H4)), """")"),"") | J8: =IFERROR(__xludf.DUMMYFUNCTION("IFERROR(INDEX(FILTER(Draft!$B$2:$B1000, Draft!$A$2:$A1000=J$1), ROW(I4)), """")"),"Davante Adams") | K8: =IFERROR(__xludf.DUMMYFUNCTION("IFERROR(INDEX(FILTER(Draft!$B$2:$B1000, Draft!$A$2:$A1000=K$1), ROW(J4)), """")"),"Jayden Daniels")
A9: 8 | B9: =IFERROR(__xludf.DUMMYFUNCTION("IFERROR(INDEX(FILTER(Draft!$B$2:$B1000, Draft!$A$2:$A1000=B$1), ROW(A5)), """")"),"TreVeyon Henderson") | C9: =IFERROR(__xludf.DUMMYFUNCTION("IFERROR(INDEX(FILTER(Draft!$B$2:$B1000, Draft!$A$2:$A1000=C$1), ROW(B5)), """")"),"Rome Odunze") | D9: =IFERROR(__xludf.DUMMYFUNCTION("IFERROR(INDEX(FILTER(Draft!$B$2:$B1000, Draft!$A$2:$A1000=D$1), ROW(C5)), """")"),"Courtland Sutton") | E9: =IFERROR(__xludf.DUMMYFUNCTION("IFERROR(INDEX(FILTER(Draft!$B$2:$B1000, Draft!$A$2:$A1000=E$1), ROW(D5)), """")"),"Harold Fannin Jr.") | F9: =IFERROR(__xludf.DUMMYFUNCTION("IFERROR(INDEX(FILTER(Draft!$B$2:$B1000, Draft!$A$2:$A1000=F$1), ROW(E5)), """")"),"") | G9: =IFERROR(__xludf.DUMMYFUNCTION("IFERROR(INDEX(FILTER(Draft!$B$2:$B1000, Draft!$A$2:$A1000=G$1), ROW(F5)), """")"),"") | H9: =IFERROR(__xludf.DUMMYFUNCTION("IFERROR(INDEX(FILTER(Draft!$B$2:$B1000, Draft!$A$2:$A1000=H$1), ROW(G5)), """")"),"RJ Harvey") | I9: =IFERROR(__xludf.DUMMYFUNCTION("IFERROR(INDEX(FILTER(Draft!$B$2:$B1000, Draft!$A$2:$A1000=I$1), ROW(H5)), """")"),"") | J9: =IFERROR(__xludf.DUMMYFUNCTION("IFERROR(INDEX(FILTER(Draft!$B$2:$B1000, Draft!$A$2:$A1000=J$1), ROW(I5)), """")"),"Luther Burden III") | K9: =IFERROR(__xludf.DUMMYFUNCTION("IFERROR(INDEX(FILTER(Draft!$B$2:$B1000, Draft!$A$2:$A1000=K$1), ROW(J5)), """")"),"Carnell Tate")
A10: 9 | B10: =IFERROR(__xludf.DUMMYFUNCTION("IFERROR(INDEX(FILTER(Draft!$B$2:$B1000, Draft!$A$2:$A1000=B$1), ROW(A6)), """")"),"Quinshon Judkins") | C10: =IFERROR(__xludf.DUMMYFUNCTION("IFERROR(INDEX(FILTER(Draft!$B$2:$B1000, Draft!$A$2:$A1000=C$1), ROW(B6)), """")"),"Justin Herbert") | D10: =IFERROR(__xludf.DUMMYFUNCTION("IFERROR(INDEX(FILTER(Draft!$B$2:$B1000, Draft!$A$2:$A1000=D$1), ROW(C6)), """")"),"") | E10: =IFERROR(__xludf.DUMMYFUNCTION("IFERROR(INDEX(FILTER(Draft!$B$2:$B1000, Draft!$A$2:$A1000=E$1), ROW(D6)), """")"),"") | F10: =IFERROR(__xludf.DUMMYFUNCTION("IFERROR(INDEX(FILTER(Draft!$B$2:$B1000, Draft!$A$2:$A1000=F$1), ROW(E6)), """")"),"") | G10: =IFERROR(__xludf.DUMMYFUNCTION("IFERROR(INDEX(FILTER(Draft!$B$2:$B1000, Draft!$A$2:$A1000=G$1), ROW(F6)), """")"),"") | H10: =IFERROR(__xludf.DUMMYFUNCTION("IFERROR(INDEX(FILTER(Draft!$B$2:$B1000, Draft!$A$2:$A1000=H$1), ROW(G6)), """")"),"Blake Corum") | I10: =IFERROR(__xludf.DUMMYFUNCTION("IFERROR(INDEX(FILTER(Draft!$B$2:$B1000, Draft!$A$2:$A1000=I$1), ROW(H6)), """")"),"") | J10: =IFERROR(__xludf.DUMMYFUNCTION("IFERROR(INDEX(FILTER(Draft!$B$2:$B1000, Draft!$A$2:$A1000=J$1), ROW(I6)), """")"),"Cam Skattebo") | K10: =IFERROR(__xludf.DUMMYFUNCTION("IFERROR(INDEX(FILTER(Draft!$B$2:$B1000, Draft!$A$2:$A1000=K$1), ROW(J6)), """")"),"DK Metcalf")
A11: 10 | B11: =IFERROR(__xludf.DUMMYFUNCTION("IFERROR(INDEX(FILTER(Draft!$B$2:$B1000, Draft!$A$2:$A1000=B$1), ROW(A7)), """")"),"Tyler Warren") | C11: =IFERROR(__xludf.DUMMYFUNCTION("IFERROR(INDEX(FILTER(Draft!$B$2:$B1000, Draft!$A$2:$A1000=C$1), ROW(B7)), """")"),"") | D11: =IFERROR(__xludf.DUMMYFUNCTION("IFERROR(INDEX(FILTER(Draft!$B$2:$B1000, Draft!$A$2:$A1000=D$1), ROW(C7)), """")"),"") | E11: =IFERROR(__xludf.DUMMYFUNCTION("IFERROR(INDEX(FILTER(Draft!$B$2:$B1000, Draft!$A$2:$A1000=E$1), ROW(D7)), """")"),"") | F11: =IFERROR(__xludf.DUMMYFUNCTION("IFERROR(INDEX(FILTER(Draft!$B$2:$B1000, Draft!$A$2:$A1000=F$1), ROW(E7)), """")"),"") | G11: =IFERROR(__xludf.DUMMYFUNCTION("IFERROR(INDEX(FILTER(Draft!$B$2:$B1000, Draft!$A$2:$A1000=G$1), ROW(F7)), """")"),"") | H11: =IFERROR(__xludf.DUMMYFUNCTION("IFERROR(INDEX(FILTER(Draft!$B$2:$B1000, Draft!$A$2:$A1000=H$1), ROW(G7)), """")"),"") | I11: =IFERROR(__xludf.DUMMYFUNCTION("IFERROR(INDEX(FILTER(Draft!$B$2:$B1000, Draft!$A$2:$A1000=I$1), ROW(H7)), """")"),"") | J11: =IFERROR(__xludf.DUMMYFUNCTION("IFERROR(INDEX(FILTER(Draft!$B$2:$B1000, Draft!$A$2:$A1000=J$1), ROW(I7)), """")"),"David Montgomery") | K11: =IFERROR(__xludf.DUMMYFUNCTION("IFERROR(INDEX(FILTER(Draft!$B$2:$B1000, Draft!$A$2:$A1000=K$1), ROW(J7)), """")"),"")
A12: 11 | B12: =IFERROR(__xludf.DUMMYFUNCTION("IFERROR(INDEX(FILTER(Draft!$B$2:$B1000, Draft!$A$2:$A1000=B$1), ROW(A8)), """")"),"") | C12: =IFERROR(__xludf.DUMMYFUNCTION("IFERROR(INDEX(FILTER(Draft!$B$2:$B1000, Draft!$A$2:$A1000=C$1), ROW(B8)), """")"),"") | D12: =IFERROR(__xludf.DUMMYFUNCTION("IFERROR(INDEX(FILTER(Draft!$B$2:$B1000, Draft!$A$2:$A1000=D$1), ROW(C8)), """")"),"") | E12: =IFERROR(__xludf.DUMMYFUNCTION("IFERROR(INDEX(FILTER(Draft!$B$2:$B1000, Draft!$A$2:$A1000=E$1), ROW(D8)), """")"),"") | F12: =IFERROR(__xludf.DUMMYFUNCTION("IFERROR(INDEX(FILTER(Draft!$B$2:$B1000, Draft!$A$2:$A1000=F$1), ROW(E8)), """")"),"") | G12: =IFERROR(__xludf.DUMMYFUNCTION("IFERROR(INDEX(FILTER(Draft!$B$2:$B1000, Draft!$A$2:$A1000=G$1), ROW(F8)), """")"),"") | H12: =IFERROR(__xludf.DUMMYFUNCTION("IFERROR(INDEX(FILTER(Draft!$B$2:$B1000, Draft!$A$2:$A1000=H$1), ROW(G8)), """")"),"") | I12: =IFERROR(__xludf.DUMMYFUNCTION("IFERROR(INDEX(FILTER(Draft!$B$2:$B1000, Draft!$A$2:$A1000=I$1), ROW(H8)), """")"),"") | J12: =IFERROR(__xludf.DUMMYFUNCTION("IFERROR(INDEX(FILTER(Draft!$B$2:$B1000, Draft!$A$2:$A1000=J$1), ROW(I8)), """")"),"Bhayshul Tuten") | K12: =IFERROR(__xludf.DUMMYFUNCTION("IFERROR(INDEX(FILTER(Draft!$B$2:$B1000, Draft!$A$2:$A1000=K$1), ROW(J8)), """")"),"")
A13: 12 | B13: =IFERROR(__xludf.DUMMYFUNCTION("IFERROR(INDEX(FILTER(Draft!$B$2:$B1000, Draft!$A$2:$A1000=B$1), ROW(A9)), """")"),"") | C13: =IFERROR(__xludf.DUMMYFUNCTION("IFERROR(INDEX(FILTER(Draft!$B$2:$B1000, Draft!$A$2:$A1000=C$1), ROW(B9)), """")"),"") | D13: =IFERROR(__xludf.DUMMYFUNCTION("IFERROR(INDEX(FILTER(Draft!$B$2:$B1000, Draft!$A$2:$A1000=D$1), ROW(C9)), """")"),"") | E13: =IFERROR(__xludf.DUMMYFUNCTION("IFERROR(INDEX(FILTER(Draft!$B$2:$B1000, Draft!$A$2:$A1000=E$1), ROW(D9)), """")"),"") | F13: =IFERROR(__xludf.DUMMYFUNCTION("IFERROR(INDEX(FILTER(Draft!$B$2:$B1000, Draft!$A$2:$A1000=F$1), ROW(E9)), """")"),"") | G13: =IFERROR(__xludf.DUMMYFUNCTION("IFERROR(INDEX(FILTER(Draft!$B$2:$B1000, Draft!$A$2:$A1000=G$1), ROW(F9)), """")"),"") | H13: =IFERROR(__xludf.DUMMYFUNCTION("IFERROR(INDEX(FILTER(Draft!$B$2:$B1000, Draft!$A$2:$A1000=H$1), ROW(G9)), """")"),"") | I13: =IFERROR(__xludf.DUMMYFUNCTION("IFERROR(INDEX(FILTER(Draft!$B$2:$B1000, Draft!$A$2:$A1000=I$1), ROW(H9)), """")"),"") | J13: =IFERROR(__xludf.DUMMYFUNCTION("IFERROR(INDEX(FILTER(Draft!$B$2:$B1000, Draft!$A$2:$A1000=J$1), ROW(I9)), """")"),"Kyle Monangai") | K13: =IFERROR(__xludf.DUMMYFUNCTION("IFERROR(INDEX(FILTER(Draft!$B$2:$B1000, Draft!$A$2:$A1000=K$1), ROW(J9)), """")"),"")

Sheet Picks
A1: TouchDownSyndrome75 | B1: MonsieurExcuses | C1: peterbar | D1: iackkkk | E1: ThomasMonette | F1: PhilB10 | G1: jflafond | H1: JeromeJ | I1: parleurmouille | J1: Fred
A2: 2026 2nd Rd (jflafond) | B2: 2026 1st Rd (PhilB10) | C2: 2026 1st Rd (iackkkk) | D2: 2026 2nd Rd (parleurmouille) | E2: 2026 1st Rd | F2: 2026 3rd Rd (TouchDownSyndrome75) | G2: 2026 3rd Rd (parleurmouille) | H2: 2026 6th Rd | I2: 2026 1st Rd (MonsieurExcuses) | J2: 2026 1st Rd (jflafond)
A3: 2026 2nd Rd (ThomasMonette) | B3: 2026 2nd Rd (iackkkk) | C3: 2026 2nd Rd | D3: 2026 3rd Rd (MonsieurExcuses) | E3: 2026 3rd Rd | F3: 2026 3rd Rd (jflafond) | G3: 2026 3rd Rd (JeromeJ) | H3: 2026 7th Rd | I3: 2026 1st Rd (JeromeJ) | J3: 2026 1st Rd (TouchDownSyndrome75)
A4: 2026 2nd Rd | B4: 2026 3rd Rd (peterbar) | C4: 2026 2nd Rd (MonsieurExcuses) | D4: 2026 5th Rd (parleurmouille) | E4: 2026 5th Rd (TouchDownSyndrome75) | F4: 2026 4th Rd | G4: 2026 4th Rd (JeromeJ) | H4: 2026 8th Rd | I4: 2026 1st Rd (peterbar) | J4: 2026 1st Rd
A5: 2026 2nd Rd (PhilB10) | B5: 2026 3rd Rd (iackkkk) | C5: 2026 4th Rd | D5: 2026 5th Rd (FredCourville) | E5: 2026 6th Rd | F5: 2026 5th Rd | G5: 2026 4th Rd | H5: 2026 9th Rd | I5: 2026 1st Rd | J5: 2026 2nd Rd (JeromeJ)
A6: 2026 3rd Rd (PhilB10) | B6: 2026 4th Rd | C6: 2026 5th Rd | D6: 2026 5th Rd | E6: 2026 7th Rd | F6: 2026 6th Rd | G6: 2026 5th Rd (ThomasMonette) | H6: 2026 11th Rd | I6: 2026 3rd Rd (FredCourville) | J6: 2026 2nd Rd
A7: 2026 4th Rd (ThomasMonette) | B7: 2026 5th Rd | C7: 2026 6th Rd | D7: 2026 6th Rd | E7: 2026 8th Rd | F7: 2026 7th Rd | G7: 2026 6th Rd | H7: 2026 12th Rd | I7: 2026 4th Rd (TouchDownSyndrome75) | J7: 2026 5th Rd (JeromeJ)
A8: 2026 4th Rd (iackkkk) | B8: 2026 6th Rd (parleurmouille) | C8: 2026 7th Rd | D8: 2026 8th Rd | E8: 2026 9th Rd | F8: 2026 8th Rd | G8: 2026 7th Rd | H8: 2026 13th Rd | I8: 2026 4th Rd (FredCourville) | J8: 2026 6th Rd
A9: 2026 6th Rd | B9: 2026 6th Rd | C9: 2026 8th Rd | D9: 2026 9th Rd (parleurmouille) | E9: 2026 10th Rd (JeromeJ) | F9: 2026 9th Rd | G9: 2026 8th Rd | H9: 2026 14th Rd | I9: 2026 4th Rd | J9: 2026 7th Rd
A10: 2026 7th Rd | B10: 2026 7th Rd (iackkkk) | C10: 2026 9th Rd | D10: 2026 9th Rd | E10: 2026 10th Rd | F10: 2026 10th Rd | G10: 2026 9th Rd | H10: 2026 15th Rd | I10: 2026 5th Rd (jflafond) | J10: 2026 8th Rd (parleurmouille)
A11: 2026 8th Rd | B11: 2026 7th Rd | C11: 2026 10th Rd | D11: 2026 10th Rd | E11: 2026 11th Rd (parleurmouille) | F11: 2026 11th Rd | G11: 2026 10th Rd | I11: 2026 7th Rd | J11: 2026 8th Rd
A12: 2026 9th Rd | B12: 2026 8th Rd | C12: 2026 11th Rd | D12: 2026 11th Rd | E12: 2026 11th Rd | F12: 2026 11th Rd (TouchDownSyndrome75) | G12: 2026 11th Rd | I12: 2026 10th Rd | J12: 2026 9th Rd
A13: 2026 10th Rd | B13: 2026 9th Rd | C13: 2026 12th Rd | D13: 2026 12th Rd | E13: 2026 12th Rd (TouchDownSyndrome75) | F13: 2026 12th Rd | G13: 2026 12th Rd | I13: 2026 12th Rd | J13: 2026 10th Rd
B14: 2026 10th Rd | C14: 2026 13th Rd | D14: 2026 13th Rd | E14: 2026 12th Rd | F14: 2026 13th Rd | G14: 2026 13th Rd | I14: 2026 13th Rd | J14: 2026 11th Rd
B15: 2026 11th Rd | C15: 2026 14th Rd | D15: 2026 14th Rd | E15: 2026 13th Rd | F15: 2026 13th Rd (TouchDownSyndrome75) | G15: 2026 14th Rd | I15: 2026 14th Rd | J15: 2026 12th Rd
B16: 2026 12th Rd | C16: 2026 15th Rd | D16: 2026 15th Rd | E16: 2026 14th Rd | F16: 2026 14th Rd | G16: 2026 15th Rd | I16: 2026 15th Rd | J16: 2026 13th Rd
B17: 2026 13th Rd | E17: 2026 15th Rd | F17: 2026 14th Rd (TouchDownSyndrome75) | J17: 2026 14th Rd
B18: 2026 14th Rd | F18: 2026 15th Rd | J18: 2026 15th Rd
B19: 2026 15th Rd | F19: 2026 15th Rd (TouchDownSyndrome75)

Sheet Fantasypro
A1: RK | B1: TIERS | C1: PLAYER NAME | D1: TEAM | E1: POS | F1: BEST | G1: WORST | H1: AVG. | I1: STD.DEV | J1: ECR VS. ADP | K1: POS
A2: 1 | B2: 1 | C2: Bijan Robinson | D2: ATL | E2: RB1 | F2: 1 | G2: 5 | H2: 1.3 | I2: 1 | J2: - | K2: =LEFT(E2,2)
A3: 2 | B3: 1 | C3: Puka Nacua | D3: LAR | E3: WR1 | F3: 2 | G3: 4 | H3: 2.2 | I3: 0.5 | J3: - | K3: =LEFT(E3,2)
A4: 3 | B4: 1 | C4: Jahmyr Gibbs | D4: DET | E4: RB2 | F4: 1 | G4: 5 | H4: 3.2 | I4: 1 | J4: - | K4: =LEFT(E4,2)
A5: 4 | B5: 2 | C5: Ja'Marr Chase | D5: CIN | E5: WR2 | F5: 4 | G5: 6 | H5: 4.6 | I5: 0.9 | J5: - | K5: =LEFT(E5,2)
A6: 5 | B6: 2 | C6: Jaxon Smith-Njigba | D6: SEA | E6: WR3 | F6: 4 | G6: 6 | H6: 5.3 | I6: 1 | J6: - | K6: =LEFT(E6,2)
A7: 6 | B7: 2 | C7: Jonathan Taylor | D7: IND | E7: RB3 | F7: 3 | G7: 8 | H7: 5.8 | I7: 1.9 | J7: - | K7: =LEFT(E7,2)
A8: 7 | B8: 2 | C8: CeeDee Lamb | D8: DAL | E8: WR4 | F8: 7 | G8: 14 | H8: 8.1 | I8: 1.8 | J8: - | K8: =LEFT(E8,2)
A9: 8 | B9: 2 | C9: Amon-Ra St. Brown | D9: DET | E9: WR5 | F9: 7 | G9: 9 | H9: 8.4 | I9: 0.9 | J9: - | K9: =LEFT(E9,2)
A10: 9 | B10: 2 | C10: Christian McCaffrey | D10: SF | E10: RB4 | F10: 5 | G10: 15 | H10: 9.3 | I10: 2.7 | J10: - | K10: =LEFT(E10,2)
A11: 10 | B11: 3 | C11: James Cook III | D11: BUF | E11: RB5 | F11: 3 | G11: 15 | H11: 10.8 | I11: 3.3 | J11: - | K11: =LEFT(E11,2)
A12: 11 | B12: 3 | C12: Malik Nabers | D12: NYG | E12: WR6 | F12: 10 | G12: 19 | H12: 12.1 | I12: 2.7 | J12: - | K12: =LEFT(E12,2)
A13: 12 | B13: 3 | C13: Justin Jefferson | D13: MIN | E13: WR7 | F13: 10 | G13: 21 | H13: 13.3 | I13: 4.1 | J13: - | K13: =LEFT(E13,2)
... A91: 90 | B91: 8 | C91: Brock Purdy | D91: SF | E91: QB12 | F91: 73 | G91: 103 | H91: 90.7 | I91: 10.2 | J91: - | K91: =LEFT(E91,2)
B92: 8 | K92: =LEFT(E92,2)
A93: 91 | B93: 8 | C93: Patrick Mahomes II | D93: KC | E93: QB13 | F93: 73 | G93: 104 | H93: 92.1 | I93: 11.3 | J93: - | K93: =LEFT(E93,2)
A94: 92 | B94: 8 | C94: Chuba Hubbard | D94: CAR | E94: RB34 | F94: 66 | G94: 117 | H94: 92.3 | I94: 15.1 | J94: - | K94: =LEFT(E94,2)
A95: 93 | B95: 8 | C95: Michael Wilson | D95: ARI | E95: WR38 | F95: 74 | G95: 120 | H95: 92.8 | I95: 13.1 | J95: - | K95: =LEFT(E95,2)
A96: 94 | B96: 8 | C96: Jordan Addison | D96: MIN | E96: WR39 | F96: 81 | G96: 116 | H96: 94.1 | I96: 8.7 | J96: - | K96: =LEFT(E96,2)
A97: 95 | B97: 9 | C97: Zach Charbonnet | D97: SEA | E97: RB35 | F97: 60 | G97: 163 | H97: 95.2 | I97: 20.9 | J97: - | K97: =LEFT(E97,2)
A98: 96 | B98: 9 | C98: Chris Godwin Jr. | D98: TB | E98: WR40 | F98: 80 | G98: 115 | H98: 96.8 | I98: 10.6 | J98: - | K98: =LEFT(E98,2)
A99: 97 | B99: 9 | C99: J.K. Dobbins | D99: DEN | E99: RB36 | F99: 64 | G99: 140 | H99: 101 | I99: 22.4 | J99: - | K99: =LEFT(E99,2)
A100: 98 | B100: 9 | C100: Dalton Kincaid | D100: BUF | E100: TE9 | F100: 94 | G100: 130 | H100: 101 | I100: 12.9 | J100: - | K100: =LEFT(E100,2)
A101: 99 | B101: 9 | C101: Jacory Croskey-Merritt | D101: WAS | E101: RB37 | F101: 87 | G101: 121 | H101: 104 | I101: 10.3 | J101: - | K101: =LEFT(E101,2)
A102: 100 | B102: 9 | C102: Bo Nix | D102: DEN | E102: QB14 | F102: 97 | G102: 112 | H102: 104 | I102: 4.3 | J102: - | K102: =LEFT(E102,2)
A103: 101 | B103: 9 | C103: Matthew Stafford | D103: LAR | E103: QB15 | F103: 90 | G103: 118 | H103: 104 | I103: 5.6 | J103: - | K103: =LEFT(E103,2)
A104: 102 | B104: 9 | C104: Ricky Pearsall | D104: SF | E104: WR41 | F104: 91 | G104: 122 | H104: 104 | I104: 7.9 | J104: - | K104: =LEFT(E104,2)
... A352: 350 | B352: 15 | C352: Antonio Williams | D352: FA | E352: WR122 | F352: 194 | G352: 268 | H352: 231 | I352: 37 | J352: - | K352: =LEFT(E352,2)
A353: 351 | B353: 15 | C353: Chicago Bears | D353: CHI | E353: DST22 | F353: 185 | G353: 278 | H353: 232 | I353: 46.5 | J353: -
A354: 352 | B354: 15 | C354: Jawhar Jordan | D354: HOU | E354: RB106 | F354: 315 | G354: 328 | H354: 321 | I354: 5.5 | J354: -
A355: 353 | B355: 15 | C355: Darnell Washington | D355: PIT | E355: TE44 | F355: 262 | G355: 341 | H355: 306 | I355: 35.6 | J355: -
A356: 354 | B356: 15 | C356: Dameon Pierce | D356: PHI | E356: RB107 | F356: 306 | G356: 381 | H356: 323 | I356: 28.9 | J356: -
A357: 355 | B357: 15 | C357: Raheim Sanders | D357: CLE | E357: RB108 | F357: 312 | G357: 363 | H357: 325 | I357: 19.4 | J357: -
A358: 356 | B358: 15 | C358: Terrell Jennings | D358: NE | E358: RB109 | F358: 308 | G358: 383 | H358: 326 | I358: 28.7 | J358: -
A359: 357 | B359: 15 | C359: Antonio Gibson | D359: FA | E359: RB110 | F359: 309 | G359: 387 | H359: 328 | I359: 29.9 | J359: -
A360: 358 | B360: 15 | C360: Justin Fields | D360: KC | E360: QB41 | F360: 307 | G360: 355 | H360: 328 | I360: 16.2 | J360: -
A361: 359 | B361: 15 | C361: Tutu Atwell | D361: MIA | E361: WR123 | F361: 203 | G361: 375 | H361: 295 | I361: 70.7 | J361: -
A362: 360 | B362: 15 | C362: Miami Dolphins | D362: MIA | E362: DST23 | F362: 319 | G362: 355 | H362: 329 | I362: 13.7 | J362: -
A363: 361 | B363: 15 | C363: Tyler Higbee | D363: LAR | E363: TE45 | F363: 258 | G363: 359 | H363: 318 | I363: 40.4 | J363: -
A364: 362 | B364: 16 | C364: Michael Mayer | D364: LV | E364: TE46 | F364: 275 | G364: 377 | H364: 325 | I364: 36.1 | J364: -
...

Sheet Keeper
A1: Iack | B1: De'Von Achane
A2: Iack | B2: Ashton Jeanty
A3: Iack | B3: Amon-Ra St. Brown
A4: Web | B4: Omarion Hampton
A5: Web | B5: Bijan Robinson
A6: Web | B6: Nico Collins
A7: Kev | B7: Jahmyr Gibbs
A8: Kev | B8: Rashee Rice
A9: Kev | B9: George Pickens
A10: JF | B10: Saquon Barkley
A11: JF | B11: Jaxon Smith-Njigba
A12: JF | B12: James Cook III
... A30: Jerome | B30: Josh Allen

Sheet Draft
A1: Draft Picks | B1: Joueurs
A2: Web | B2: =IFERROR(__xludf.DUMMYFUNCTION("FILTER('ALL PPR Drafts'!D2:D1000, ('ALL PPR Drafts'!C2:C1000<>""x"")*('ALL PPR Drafts'!D2:D1000<>""""))"),"Jeremiyah Love")
A3: Hugo | B3: =IFERROR(__xludf.DUMMYFUNCTION("""COMPUTED_VALUE"""),"Derrick Henry")
A4: Kev | B4: =IFERROR(__xludf.DUMMYFUNCTION("""COMPUTED_VALUE"""),"Lamar Jackson")
A5: Fred | B5: =IFERROR(__xludf.DUMMYFUNCTION("""COMPUTED_VALUE"""),"Tee Higgins")
A6: Web | B6: =IFERROR(__xludf.DUMMYFUNCTION("""COMPUTED_VALUE"""),"Kenneth Walker III")
A7: Fred | B7: =IFERROR(__xludf.DUMMYFUNCTION("""COMPUTED_VALUE"""),"A.J. Brown")
A8: Web | B8: =IFERROR(__xludf.DUMMYFUNCTION("""COMPUTED_VALUE"""),"Josh Jacobs")
A9: Web | B9: =IFERROR(__xludf.DUMMYFUNCTION("""COMPUTED_VALUE"""),"Davante Adams")
A10: Fred | B10: =IFERROR(__xludf.DUMMYFUNCTION("""COMPUTED_VALUE"""),"Breece Hall")
A11: Thomas | B11: =IFERROR(__xludf.DUMMYFUNCTION("""COMPUTED_VALUE"""),"Tucker Kraft")
A12: Iack | B12: =IFERROR(__xludf.DUMMYFUNCTION("""COMPUTED_VALUE"""),"Zay Flowers")
A13: Kev | B13: =IFERROR(__xludf.DUMMYFUNCTION("""COMPUTED_VALUE"""),"Joe Burrow")
A14: Phil | B14: =IFERROR(__xludf.DUMMYFUNCTION("""COMPUTED_VALUE"""),"Javonte Williams")
A15: Ben | B15: =IFERROR(__xludf.DUMMYFUNCTION("""COMPUTED_VALUE"""),"Travis Etienne Jr.")
A16: Hugo | B16: =IFERROR(__xludf.DUMMYFUNCTION("""COMPUTED_VALUE"""),"Jameson Williams")
A17: Fred | B17: =IFERROR(__xludf.DUMMYFUNCTION("""COMPUTED_VALUE"""),"Jayden Daniels")
A18: Fred | B18: =IFERROR(__xludf.DUMMYFUNCTION("""COMPUTED_VALUE"""),"Carnell Tate")
A19: Kev | B19: =IFERROR(__xludf.DUMMYFUNCTION("""COMPUTED_VALUE"""),"Bucky Irving")
A20: Ben | B20: =IFERROR(__xludf.DUMMYFUNCTION("""COMPUTED_VALUE"""),"Ladd McConkey")
A21: Ben | B21: =IFERROR(__xludf.DUMMYFUNCTION("""COMPUTED_VALUE"""),"Terry McLaurin")
A22: JF | B22: =IFERROR(__xludf.DUMMYFUNCTION("""COMPUTED_VALUE"""),"Colston Loveland")
A23: Kev | B23: =IFERROR(__xludf.DUMMYFUNCTION("""COMPUTED_VALUE"""),"Jaylen Waddle")
A24: Ben | B24: =IFERROR(__xludf.DUMMYFUNCTION("""COMPUTED_VALUE"""),"Christian Watson")
A25: Ben | B25: =IFERROR(__xludf.DUMMYFUNCTION("""COMPUTED_VALUE"""),"TreVeyon Henderson")
A26: Hugo | B26: =IFERROR(__xludf.DUMMYFUNCTION("""COMPUTED_VALUE"""),"Jalen Hurts")
A27: Web | B27: =IFERROR(__xludf.DUMMYFUNCTION("""COMPUTED_VALUE"""),"Luther Burden III")
A28: JF | B28: =IFERROR(__xludf.DUMMYFUNCTION("""COMPUTED_VALUE"""),"Emeka Egbuka")
A29: Iack | B29: =IFERROR(__xludf.DUMMYFUNCTION("""COMPUTED_VALUE"""),"Mike Evans")
A30: JF | B30: =IFERROR(__xludf.DUMMYFUNCTION("""COMPUTED_VALUE"""),"DeVonta Smith")
A31: Thomas | B31: =IFERROR(__xludf.DUMMYFUNCTION("""COMPUTED_VALUE"""),"D'Andre Swift")
A32: Web | B32: =IFERROR(__xludf.DUMMYFUNCTION("""COMPUTED_VALUE"""),"Cam Skattebo")
A33: Ben | B33: =IFERROR(__xludf.DUMMYFUNCTION("""COMPUTED_VALUE"""),"Quinshon Judkins")
A34: Phil | B34: =IFERROR(__xludf.DUMMYFUNCTION("""COMPUTED_VALUE"""),"Makai Lemon")
A35: Web | B35: =IFERROR(__xludf.DUMMYFUNCTION("""COMPUTED_VALUE"""),"David Montgomery")
A36: Hugo | B36: =IFERROR(__xludf.DUMMYFUNCTION("""COMPUTED_VALUE"""),"DJ Moore")
A37: Web | B37: =IFERROR(__xludf.DUMMYFUNCTION("""COMPUTED_VALUE"""),"Bhayshul Tuten")
A38: JF | B38: =IFERROR(__xludf.DUMMYFUNCTION("""COMPUTED_VALUE"""),"Jordyn Tyson")
A39: Kev | B39: =IFERROR(__xludf.DUMMYFUNCTION("""COMPUTED_VALUE"""),"Rome Odunze")
A40: JF | B40: =IFERROR(__xludf.DUMMYFUNCTION("""COMPUTED_VALUE"""),"RJ Harvey")
...

Sheet Tiers_Risk
B1: Rank
A2: Average
A3: 1-10 | B3: =IFERROR(__xludf.DUMMYFUNCTION("TRANSPOSE( FILTER( IF( 'ALL PPR Drafts'!C$2:C1000 = """", 'ALL PPR Drafts'!D$2:D1000 & "" ("" & 'ALL PPR Drafts'!F$2:F1000 & "", "" & 'ALL PPR Drafts'!H$2:H1000 & "", "" & 'ALL PPR Drafts'!I$2:I1000 & "")"", """" ), VALUE("&"'ALL PPR Drafts'!G$2:G1000) >= 1, VALUE('ALL PPR Drafts'!G$2:G1000) <= 10.99 ) ) "),"") | C3: =IFERROR(__xludf.DUMMYFUNCTION("""COMPUTED_VALUE"""),"") | D3: =IFERROR(__xludf.DUMMYFUNCTION("""COMPUTED_VALUE"""),"") | E3: =IFERROR(__xludf.DUMMYFUNCTION("""COMPUTED_VALUE"""),"") | F3: =IFERROR(__xludf.DUMMYFUNCTION("""COMPUTED_VALUE"""),"") | G3: =IFERROR(__xludf.DUMMYFUNCTION("""COMPUTED_VALUE"""),"") | H3: =IFERROR(__xludf.DUMMYFUNCTION("""COMPUTED_VALUE"""),"") | I3: =IFERROR(__xludf.DUMMYFUNCTION("""COMPUTED_VALUE"""),"") | J3: =IFERROR(__xludf.DUMMYFUNCTION("""COMPUTED_VALUE"""),"") | K3: =IFERROR(__xludf.DUMMYFUNCTION("""COMPUTED_VALUE"""),"")
A4: 11-20 | B4: =IFERROR(__xludf.DUMMYFUNCTION("TRANSPOSE( FILTER( IF( 'ALL PPR Drafts'!C$2:C1000 = """", 'ALL PPR Drafts'!D$2:D1000 & "" ("" & 'ALL PPR Drafts'!F$2:F1000 & "", "" & 'ALL PPR Drafts'!H$2:H1000 & "", "" & 'ALL PPR Drafts'!I$2:I1000 & "")"", """" ), VALUE('"&"ALL PPR Drafts'!G$2:G1000) >= 11, VALUE('ALL PPR Drafts'!G$2:G1000) <= 20.99 ) ) "),"") | C4: =IFERROR(__xludf.DUMMYFUNCTION("""COMPUTED_VALUE"""),"") | D4: =IFERROR(__xludf.DUMMYFUNCTION("""COMPUTED_VALUE"""),"") | E4: =IFERROR(__xludf.DUMMYFUNCTION("""COMPUTED_VALUE"""),"") | F4: =IFERROR(__xludf.DUMMYFUNCTION("""COMPUTED_VALUE"""),"") | G4: =IFERROR(__xludf.DUMMYFUNCTION("""COMPUTED_VALUE"""),"") | H4: =IFERROR(__xludf.DUMMYFUNCTION("""COMPUTED_VALUE"""),"") | I4: =IFERROR(__xludf.DUMMYFUNCTION("""COMPUTED_VALUE"""),"Jeremiyah Love (RB, 4.2, 3)") | J4: =IFERROR(__xludf.DUMMYFUNCTION("""COMPUTED_VALUE"""),"") | K4: =IFERROR(__xludf.DUMMYFUNCTION("""COMPUTED_VALUE"""),"")
A5: 21-30 | B5: =IFERROR(__xludf.DUMMYFUNCTION("TRANSPOSE( FILTER( IF( 'ALL PPR Drafts'!C$2:C1000 = """", 'ALL PPR Drafts'!D$2:D1000 & "" ("" & 'ALL PPR Drafts'!F$2:F1000 & "", "" & 'ALL PPR Drafts'!H$2:H1000 & "", "" & 'ALL PPR Drafts'!I$2:I1000 & "")"", """" ), VALUE('"&"ALL PPR Drafts'!G$2:G1000) >= 21, VALUE('ALL PPR Drafts'!G$2:G1000) <= 30.99 ) ) "),"") | C5: =IFERROR(__xludf.DUMMYFUNCTION("""COMPUTED_VALUE"""),"") | D5: =IFERROR(__xludf.DUMMYFUNCTION("""COMPUTED_VALUE"""),"") | E5: =IFERROR(__xludf.DUMMYFUNCTION("""COMPUTED_VALUE"""),"Derrick Henry (RB, 4.8, 1)") | F5: =IFERROR(__xludf.DUMMYFUNCTION("""COMPUTED_VALUE"""),"") | G5: =IFERROR(__xludf.DUMMYFUNCTION("""COMPUTED_VALUE"""),"") | H5: =IFERROR(__xludf.DUMMYFUNCTION("""COMPUTED_VALUE"""),"Lamar Jackson (QB, 1.2, 3)") | I5: =IFERROR(__xludf.DUMMYFUNCTION("""COMPUTED_VALUE"""),"Tee Higgins (WR, 5.3, 3)") | J5: =IFERROR(__xludf.DUMMYFUNCTION("""COMPUTED_VALUE"""),"Kenneth Walker III (RB, 8.3, 3)") | K5: =IFERROR(__xludf.DUMMYFUNCTION("""COMPUTED_VALUE"""),"A.J. Brown (WR, 5.3, 3)") | L5: =IFERROR(__xludf.DUMMYFUNCTION("""COMPUTED_VALUE"""),"")
A6: 31-40 | B6: =IFERROR(__xludf.DUMMYFUNCTION("TRANSPOSE( FILTER( IF( 'ALL PPR Drafts'!C$2:C1000 = """", 'ALL PPR Drafts'!D$2:D1000 & "" ("" & 'ALL PPR Drafts'!F$2:F1000 & "", "" & 'ALL PPR Drafts'!H$2:H1000 & "", "" & 'ALL PPR Drafts'!I$2:I1000 & "")"", """" ), VALUE('"&"ALL PPR Drafts'!G$2:G1000) >= 31, VALUE('ALL PPR Drafts'!G$2:G1000) <= 40.99 ) ) "),"Josh Jacobs (RB, 7.7, 4)") | C6: =IFERROR(__xludf.DUMMYFUNCTION("""COMPUTED_VALUE"""),"") | D6: =IFERROR(__xludf.DUMMYFUNCTION("""COMPUTED_VALUE"""),"") | E6: =IFERROR(__xludf.DUMMYFUNCTION("""COMPUTED_VALUE"""),"Davante Adams (WR, 5, 3)") | F6: =IFERROR(__xludf.DUMMYFUNCTION("""COMPUTED_VALUE"""),"")
A7: 41-50 | B7: =IFERROR(__xludf.DUMMYFUNCTION("TRANSPOSE( FILTER( IF( 'ALL PPR Drafts'!C$2:C1000 = """", 'ALL PPR Drafts'!D$2:D1000 & "" ("" & 'ALL PPR Drafts'!F$2:F1000 & "", "" & 'ALL PPR Drafts'!H$2:H1000 & "","" & 'ALL PPR Drafts'!I$2:I1000 & "")"", """" ), VALUE('A"&"LL PPR Drafts'!G$2:G1000) >= 41, VALUE('ALL PPR Drafts'!G$2:G1000) <= 50.99 ) ) "),"Breece Hall (RB, 5.8,4)") | C7: =IFERROR(__xludf.DUMMYFUNCTION("""COMPUTED_VALUE"""),"Tucker Kraft (TE, 20.4,2)") | D7: =IFERROR(__xludf.DUMMYFUNCTION("""COMPUTED_VALUE"""),"") | E7: =IFERROR(__xludf.DUMMYFUNCTION("""COMPUTED_VALUE"""),"Zay Flowers (WR, 8.4,4)") | F7: =IFERROR(__xludf.DUMMYFUNCTION("""COMPUTED_VALUE"""),"Joe Burrow (QB, 10.7,3)") | G7: =IFERROR(__xludf.DUMMYFUNCTION("""COMPUTED_VALUE"""),"Javonte Williams (RB, 7.9,3)") | H7: =IFERROR(__xludf.DUMMYFUNCTION("""COMPUTED_VALUE"""),"Travis Etienne Jr. (RB, 5.7,3)") | I7: =IFERROR(__xludf.DUMMYFUNCTION("""COMPUTED_VALUE"""),"Jameson Williams (WR, 7.7,4)") | J7: =IFERROR(__xludf.DUMMYFUNCTION("""COMPUTED_VALUE"""),"Jayden Daniels (QB, 11.3,4)") | K7: =IFERROR(__xludf.DUMMYFUNCTION("""COMPUTED_VALUE"""),"Carnell Tate (WR, 13.9,3)") | L7: =IFERROR(__xludf.DUMMYFUNCTION("""COMPUTED_VALUE"""),"Bucky Irving (RB, 4.7,3)") | M7: =IFERROR(__xludf.DUMMYFUNCTION("""COMPUTED_VALUE"""),"Ladd McConkey (WR, 6.1,3)") | N7: =IFERROR(__xludf.DUMMYFUNCTION("""COMPUTED_VALUE"""),"Terry McLaurin (WR, 6.9,4)") | O7: =IFERROR(__xludf.DUMMYFUNCTION("""COMPUTED_VALUE"""),"Colston Loveland (TE, 11,4)")
A8: 51-60 | B8: =IFERROR(__xludf.DUMMYFUNCTION("TRANSPOSE( FILTER( IF( 'ALL PPR Drafts'!C$2:C1000 = """", 'ALL PPR Drafts'!D$2:D1000 & "" ("" & 'ALL PPR Drafts'!F$2:F1000 & "","" & 'ALL PPR Drafts'!H$2:H1000 & "", "" & 'ALL PPR Drafts'!I$2:I1000 & "")"", """" ), VALUE('A"&"LL PPR Drafts'!G$2:G1000) >= 51, VALUE('ALL PPR Drafts'!G$2:G1000) <= 60.99 ) ) "),"Jaylen Waddle (WR,10.6, 3)") | C8: =IFERROR(__xludf.DUMMYFUNCTION("""COMPUTED_VALUE"""),"Christian Watson (WR,8.4, 3)") | D8: =IFERROR(__xludf.DUMMYFUNCTION("""COMPUTED_VALUE"""),"TreVeyon Henderson (RB,7.7, 4)") | E8: =IFERROR(__xludf.DUMMYFUNCTION("""COMPUTED_VALUE"""),"Jalen Hurts (QB,10.7, 4)") | F8: =IFERROR(__xludf.DUMMYFUNCTION("""COMPUTED_VALUE"""),"Luther Burden III (WR,9.3, 4)") | G8: =IFERROR(__xludf.DUMMYFUNCTION("""COMPUTED_VALUE"""),"Emeka Egbuka (WR,8.8, 4)") | H8: =IFERROR(__xludf.DUMMYFUNCTION("""COMPUTED_VALUE"""),"Mike Evans (WR,11.9, 4)") | I8: =IFERROR(__xludf.DUMMYFUNCTION("""COMPUTED_VALUE"""),"DeVonta Smith (WR,9.6, 2)") | J8: =IFERROR(__xludf.DUMMYFUNCTION("""COMPUTED_VALUE"""),"D'Andre Swift (RB,4.5, 4)") | K8: =IFERROR(__xludf.DUMMYFUNCTION("""COMPUTED_VALUE"""),"Cam Skattebo (RB,9.7, 2)")
A9: 61-70 | B9: =IFERROR(__xludf.DUMMYFUNCTION("TRANSPOSE( FILTER( IF( 'ALL PPR Drafts'!C$2:C1000 = """", 'ALL PPR Drafts'!D$2:D1000 & "" ("" & 'ALL PPR Drafts'!F$2:F1000 & "","" & 'ALL PPR Drafts'!H$2:H1000 & "", "" & 'ALL PPR Drafts'!I$2:I1000 & "")"", """" ), VALUE('A"&"LL PPR Drafts'!G$2:G1000) >= 61, VALUE('ALL PPR Drafts'!G$2:G1000) <= 70.99 ) ) "),"Quinshon Judkins (RB,3.7, 4)") | C9: =IFERROR(__xludf.DUMMYFUNCTION("""COMPUTED_VALUE"""),"Makai Lemon (WR,19, 4)") | D9: =IFERROR(__xludf.DUMMYFUNCTION("""COMPUTED_VALUE"""),"David Montgomery (RB,12.5, 4)") | E9: =IFERROR(__xludf.DUMMYFUNCTION("""COMPUTED_VALUE"""),"DJ Moore (WR,17.9, 4)") | F9: =IFERROR(__xludf.DUMMYFUNCTION("""COMPUTED_VALUE"""),"Bhayshul Tuten (RB,10.4, 4)") | G9: =IFERROR(__xludf.DUMMYFUNCTION("""COMPUTED_VALUE"""),"Jordyn Tyson (WR,18.8, 4)") | H9: =IFERROR(__xludf.DUMMYFUNCTION("""COMPUTED_VALUE"""),"Rome Odunze (WR,13.2, 4)") | I9: =IFERROR(__xludf.DUMMYFUNCTION("""COMPUTED_VALUE"""),"RJ Harvey (RB,12.1, 3)") | J9: =IFERROR(__xludf.DUMMYFUNCTION("""COMPUTED_VALUE"""),"Tyler Warren (TE,5.3, 4)") | K9: =IFERROR(__xludf.DUMMYFUNCTION("""COMPUTED_VALUE"""),"Alec Pierce (WR,11.6, 4)") | L9: =IFERROR(__xludf.DUMMYFUNCTION("""COMPUTED_VALUE"""),"Jaxson Dart (QB,10.3, 4)")
A10: 71-80 | B10: =IFERROR(__xludf.DUMMYFUNCTION("TRANSPOSE( FILTER( IF( 'ALL PPR Drafts'!C$2:C1000 = """", 'ALL PPR Drafts'!D$2:D1000 & "" ("" & 'ALL PPR Drafts'!F$2:F1000 & "", "" & 'ALL PPR Drafts'!H$2:H1000 & "", "" & 'ALL PPR Drafts'!I$2:I1000 & "")"", """" ), VALUE('"&"ALL PPR Drafts'!G$2:G1000) >= 71, VALUE('ALL PPR Drafts'!G$2:G1000) <= 80.99 ) ) "),"Caleb Williams (QB, 11.3, 3)") | C10: =IFERROR(__xludf.DUMMYFUNCTION("""COMPUTED_VALUE"""),"Jaylen Warren (RB, 7.6, 4)") | D10: =IFERROR(__xludf.DUMMYFUNCTION("""COMPUTED_VALUE"""),"Courtland Sutton (WR, 10.4, 3)") | E10: =IFERROR(__xludf.DUMMYFUNCTION("""COMPUTED_VALUE"""),"Harold Fannin Jr. (TE, 7.3, 4)") | F10: =IFERROR(__xludf.DUMMYFUNCTION("""COMPUTED_VALUE"""),"#N/A") | G10: =IFERROR(__xludf.DUMMYFUNCTION("""COMPUTED_VALUE"""),"Justin Herbert (QB, 13.5, 3)") | H10: =IFERROR(__xludf.DUMMYFUNCTION("""COMPUTED_VALUE"""),"Kyle Monangai (RB, 7.1, 4)") | I10: =IFERROR(__xludf.DUMMYFUNCTION("""COMPUTED_VALUE"""),"Blake Corum (RB, 9.2, 3)")
A11: 81-90 | B11: =IFERROR(__xludf.DUMMYFUNCTION("TRANSPOSE( FILTER( IF( 'ALL PPR Drafts'!C$2:C1000 = """", 'ALL PPR Drafts'!D$2:D1000 & "" ("" & 'ALL PPR Drafts'!F$2:F1000 & "", "" & 'ALL PPR Drafts'!H$2:H1000 & "", "" & 'ALL PPR Drafts'!I$2:I1000 & "")"", """" ), VALUE('"&"ALL PPR Drafts'!G$2:G1000) >= 81, VALUE('ALL PPR Drafts'!G$2:G1000) <= 90.99 ) ) "),"Rico Dowdle (RB, 8, 4)") | C11: =IFERROR(__xludf.DUMMYFUNCTION("""COMPUTED_VALUE"""),"Marvin Harrison Jr. (WR, 9.3, 4)") | D11: =IFERROR(__xludf.DUMMYFUNCTION("""COMPUTED_VALUE"""),"Rhamondre Stevenson (RB, 9.9, 1)") | E11: =IFERROR(__xludf.DUMMYFUNCTION("""COMPUTED_VALUE"""),"Sam LaPorta (TE, 2, 4)") | F11: =IFERROR(__xludf.DUMMYFUNCTION("""COMPUTED_VALUE"""),"Trevor Lawrence (QB, 12.2, 2)") | G11: =IFERROR(__xludf.DUMMYFUNCTION("""COMPUTED_VALUE"""),"Kyle Pitts Sr. (TE, 4.2, 4)") | H11: =IFERROR(__xludf.DUMMYFUNCTION("""COMPUTED_VALUE"""),"Dak Prescott (QB, 11.8, 4)") | I11: =IFERROR(__xludf.DUMMYFUNCTION("""COMPUTED_VALUE"""),"Tyler Allgeier (RB, 13.7, 3)") | J11: =IFERROR(__xludf.DUMMYFUNCTION("""COMPUTED_VALUE"""),"Tony Pollard (RB, 12.9, 4)") | K11: =IFERROR(__xludf.DUMMYFUNCTION("""COMPUTED_VALUE"""),"#N/A")
A12: 91-100 | B12: =IFERROR(__xludf.DUMMYFUNCTION("TRANSPOSE( FILTER( IF( 'ALL PPR Drafts'!C$2:C1000 = """", 'ALL PPR Drafts'!D$2:D1000 & "" ("" & 'ALL PPR Drafts'!F$2:F1000 & "", "" & 'ALL PPR Drafts'!H$2:H1000 & "", "" & 'ALL PPR Drafts'!I$2:I1000 & "")"", """" ), VALUE('"&"ALL PPR Drafts'!G$2:G1000) >= 91, VALUE('ALL PPR Drafts'!G$2:G1000) <= 100.99 ) ) "),"Patrick Mahomes II (QB, 11.3, 4)") | C12: =IFERROR(__xludf.DUMMYFUNCTION("""COMPUTED_VALUE"""),"Chuba Hubbard (RB, 15.1, 4)") | D12: =IFERROR(__xludf.DUMMYFUNCTION("""COMPUTED_VALUE"""),"Michael Wilson (WR, 13.1, 4)") | E12: =IFERROR(__xludf.DUMMYFUNCTION("""COMPUTED_VALUE"""),"Jordan Addison (WR, 8.7, 4)") | F12: =IFERROR(__xludf.DUMMYFUNCTION("""COMPUTED_VALUE"""),"Zach Charbonnet (RB, 20.9, 4)") | G12: =IFERROR(__xludf.DUMMYFUNCTION("""COMPUTED_VALUE"""),"Chris Godwin Jr. (WR, 10.6, 4)")
A13: 101-110 | B13: =IFERROR(__xludf.DUMMYFUNCTION("TRANSPOSE( FILTER( IF( 'ALL PPR Drafts'!C$2:C1000 = """", 'ALL PPR Drafts'!D$2:D1000 & "" ("" & 'ALL PPR Drafts'!F$2:F1000 & "", "" & 'ALL PPR Drafts'!H$2:H1000 & "", "" & 'ALL PPR Drafts'!I$2:I1000 & "")"", """" ), VALUE('"&"ALL PPR Drafts'!G$2:G1000) >= 101, VALUE('ALL PPR Drafts'!G$2:G1000) <= 110.99 ) ) "),"J.K. Dobbins (RB, 22.4, 4)") | C13: =IFERROR(__xludf.DUMMYFUNCTION("""COMPUTED_VALUE"""),"Dalton Kincaid (TE, 12.9, 4)") | D13: =IFERROR(__xludf.DUMMYFUNCTION("""COMPUTED_VALUE"""),"Jacory Croskey-Merritt (RB, 10.3, 2)") | E13: =IFERROR(__xludf.DUMMYFUNCTION("""COMPUTED_VALUE"""),"Bo Nix (QB, 4.3, 3)") | F13: =IFERROR(__xludf.DUMMYFUNCTION("""COMPUTED_VALUE"""),"Matthew Stafford (QB, 5.6, 3)") | G13: =IFERROR(__xludf.DUMMYFUNCTION("""COMPUTED_VALUE"""),"Ricky Pearsall (WR, 7.9, 4)") | H13: =IFERROR(__xludf.DUMMYFUNCTION("""COMPUTED_VALUE"""),"Parker Washington (WR, 16.9, 4)") | I13: =IFERROR(__xludf.DUMMYFUNCTION("""COMPUTED_VALUE"""),"Quentin Johnston (WR, 11.5, 4)") | J13: =IFERROR(__xludf.DUMMYFUNCTION("""COMPUTED_VALUE"""),"Oronde Gadsden II (TE, 12, 4)") | K13: =IFERROR(__xludf.DUMMYFUNCTION("""COMPUTED_VALUE"""),"Michael Pittman Jr. (WR, 11.9, 4)") | L13: =IFERROR(__xludf.DUMMYFUNCTION("""COMPUTED_VALUE"""),"Woody Marks (RB, 22.3, 4)")
A14: 111-120 | B14: =IFERROR(__xludf.DUMMYFUNCTION("TRANSPOSE( FILTER( IF( 'ALL PPR Drafts'!C$2:C1000 = """", 'ALL PPR Drafts'!D$2:D1000 & "" ("" & 'ALL PPR Drafts'!F$2:F1000 & "", "" & 'ALL PPR Drafts'!H$2:H1000 & "", "" & 'ALL PPR Drafts'!I$2:I1000 & "")"", """" ), VALUE('"&"ALL PPR Drafts'!G$2:G1000) >= 111, VALUE('ALL PPR Drafts'!G$2:G1000) <= 120.99 ) ) "),"#N/A") | C14: =IFERROR(__xludf.DUMMYFUNCTION("""COMPUTED_VALUE"""),"Brandon Aiyuk (WR, 32.5, 3)") | D14: =IFERROR(__xludf.DUMMYFUNCTION("""COMPUTED_VALUE"""),"Jakobi Meyers (WR, 4.5, 3)") | E14: =IFERROR(__xludf.DUMMYFUNCTION("""COMPUTED_VALUE"""),"Jared Goff (QB, 6.8, 3)") | F14: =IFERROR(__xludf.DUMMYFUNCTION("""COMPUTED_VALUE"""),"Aaron Jones Sr. (RB, 5.3, 4)") | G14: =IFERROR(__xludf.DUMMYFUNCTION("""COMPUTED_VALUE"""),"Jake Ferguson (TE, 14.3, 4)") | H14: =IFERROR(__xludf.DUMMYFUNCTION("""COMPUTED_VALUE"""),"#N/A") | I14: =IFERROR(__xludf.DUMMYFUNCTION("""COMPUTED_VALUE"""),"Denzel Boston (WR, 32.2, 4)") | J14: =IFERROR(__xludf.DUMMYFUNCTION("""COMPUTED_VALUE"""),"Jordan Mason (RB, 10.2, 4)")
A15: 121-130 | B15: =IFERROR(__xludf.DUMMYFUNCTION("TRANSPOSE( FILTER( IF( 'ALL PPR Drafts'!C$2:C1000 = """", 'ALL PPR Drafts'!D$2:D1000 & "" ("" & 'ALL PPR Drafts'!F$2:F1000 & "", "" & 'ALL PPR Drafts'!H$2:H1000 & "", "" & 'ALL PPR Drafts'!I$2:I1000 & "")"", """" ), VALUE('"&"ALL PPR Drafts'!G$2:G1000) >= 121, VALUE('ALL PPR Drafts'!G$2:G1000) <= 130.99 ) ) "),"Juwan Johnson (TE, 15.4, 4)") | C15: =IFERROR(__xludf.DUMMYFUNCTION("""COMPUTED_VALUE"""),"James Conner (RB, 16.1, 4)") | D15: =IFERROR(__xludf.DUMMYFUNCTION("""COMPUTED_VALUE"""),"Jayden Higgins (WR, 9, 4)") | E15: =IFERROR(__xludf.DUMMYFUNCTION("""COMPUTED_VALUE"""),"#N/A") | F15: =IFERROR(__xludf.DUMMYFUNCTION("""COMPUTED_VALUE"""),"Malik Willis (QB, 24.7, 4)") | G15: =IFERROR(__xludf.DUMMYFUNCTION("""COMPUTED_VALUE"""),"Brenton Strange (TE, 17, 4)") | H15: =IFERROR(__xludf.DUMMYFUNCTION("""COMPUTED_VALUE"""),"#N/A") | I15: =IFERROR(__xludf.DUMMYFUNCTION("""COMPUTED_VALUE"""),"Kyler Murray (QB, 16.5, 3)") | J15: =IFERROR(__xludf.DUMMYFUNCTION("""COMPUTED_VALUE"""),"#N/A") | K15: =IFERROR(__xludf.DUMMYFUNCTION("""COMPUTED_VALUE"""),"Travis Kelce (TE, 29.9, 4)") | L15: =IFERROR(__xludf.DUMMYFUNCTION("""COMPUTED_VALUE"""),"#N/A")
A16: 131-140 | B16: =IFERROR(__xludf.DUMMYFUNCTION("TRANSPOSE( FILTER( IF( 'ALL PPR Drafts'!C$2:C1000 = """", 'ALL PPR Drafts'!D$2:D1000 & "" ("" & 'ALL PPR Drafts'!F$2:F1000 & "", "" & 'ALL PPR Drafts'!H$2:H1000 & "", "" & 'ALL PPR Drafts'!I$2:I1000 & "")"", """" ), VALUE('"&"ALL PPR Drafts'!G$2:G1000) >= 131, VALUE('ALL PPR Drafts'!G$2:G1000) <= 140.99 ) ) "),"#N/A") | C16: =IFERROR(__xludf.DUMMYFUNCTION("""COMPUTED_VALUE"""),"Jadarian Price (RB, 52.3, 4)") | D16: =IFERROR(__xludf.DUMMYFUNCTION("""COMPUTED_VALUE"""),"Braelon Allen (RB, 18.4, 4)") | E16: =IFERROR(__xludf.DUMMYFUNCTION("""COMPUTED_VALUE"""),"Jayden Reed (WR, 9.7, 4)") | F16: =IFERROR(__xludf.DUMMYFUNCTION("""COMPUTED_VALUE"""),"#N/A") | G16: =IFERROR(__xludf.DUMMYFUNCTION("""COMPUTED_VALUE"""),"Romeo Doubs (WR, 33.5, 4)") | H16: =IFERROR(__xludf.DUMMYFUNCTION("""COMPUTED_VALUE"""),"#N/A") | I16: =IFERROR(__xludf.DUMMYFUNCTION("""COMPUTED_VALUE"""),"George Kittle (TE, 32.5, 4)") | J16: =IFERROR(__xludf.DUMMYFUNCTION("""COMPUTED_VALUE"""),"Hunter Henry (TE, 11.5, 3)") | K16: =IFERROR(__xludf.DUMMYFUNCTION("""COMPUTED_VALUE"""),"Xavier Worthy (WR, 7.6, 3)") | L16: =IFERROR(__xludf.DUMMYFUNCTION("""COMPUTED_VALUE"""),"Khalil Shakir (WR, 8.4, 4)")
A17: 141-150 | B17: =IFERROR(__xludf.DUMMYFUNCTION("TRANSPOSE( FILTER( IF( 'ALL PPR Drafts'!C$2:C1000 = """", 'ALL PPR Drafts'!D$2:D1000 & "" ("" & 'ALL PPR Drafts'!F$2:F1000 & "", "" & 'ALL PPR Drafts'!H$2:H1000 & "", "" & 'ALL PPR Drafts'!I$2:I1000 & "")"", """" ), VALUE('"&"ALL PPR Drafts'!G$2:G1000) >= 141, VALUE('ALL PPR Drafts'!G$2:G1000) <= 150.99 ) ) "),"C.J. Stroud (QB, 10.9, 4)") | C17: =IFERROR(__xludf.DUMMYFUNCTION("""COMPUTED_VALUE"""),"#N/A") | D17: =IFERROR(__xludf.DUMMYFUNCTION("""COMPUTED_VALUE"""),"Emmett Johnson (RB, 42.5, 4)") | E17: =IFERROR(__xludf.DUMMYFUNCTION("""COMPUTED_VALUE"""),"#N/A") | F17: =IFERROR(__xludf.DUMMYFUNCTION("""COMPUTED_VALUE"""),"Stefon Diggs (WR, 49, 4)") | G17: =IFERROR(__xludf.DUMMYFUNCTION("""COMPUTED_VALUE"""),"Alvin Kamara (RB, 21.6, 4)") | H17: =IFERROR(__xludf.DUMMYFUNCTION("""COMPUTED_VALUE"""),"#N/A") | I17: =IFERROR(__xludf.DUMMYFUNCTION("""COMPUTED_VALUE"""),"#N/A") | J17: =IFERROR(__xludf.DUMMYFUNCTION("""COMPUTED_VALUE"""),"Houston Texans (DS, 0, 4)") | K17: =IFERROR(__xludf.DUMMYFUNCTION("""COMPUTED_VALUE"""),"Jonathon Brooks (RB, 26.3, 4)")

Sheet ALL PPR Drafts
B1: x | C1: Taken | D1: PLAYER NAME | E1: TEAM | F1: POS | G1: AVG. | H1: STD.DEV
C2: =IF(COUNTIF(Keeper!B:B,D2)>0,"x","") | D2: =Fantasypro!C2 | E2: =Fantasypro!D2 | F2: =Fantasypro!K2 | G2: =Fantasypro!H2 | H2: =Fantasypro!I2 | I2: =_xludf.IFS( F3 = "RB", _xludf.IFS( AND(H3 >= 0, H3 < 2.55), 1, AND(H3 >= 2.55, H3 < 4.7), 2, AND(H3 >= 4.7, H3 < 8.4), 3, AND(H3 >= 8.4, H3 <= 36), 4 ), F3 = "WR", _xludf.IFS( AND(H3 >= 0, H3 < 2.55), 1, AND(H3 >= 2.55, H3 < 4.2), 2, AND(H3 >= 4.2, H3 < 8.55), 3, AND(H3 >= 8.55, H3 <= 24.4), 4 ), F3 = "QB", _xludf.IFS( AND(H3 >= 0, H3 < 2.95), 1, AND(H3 >= 2.95, H3 < 5.4), 2, AND(H3 >= 5.4, H3 < 7.2), 3, AND(H3 >= 7.2, H3 <= 12.3), 4 ), F3 = "TE", _xludf.IFS( AND(H3 >= 0, H3 < 3), 1, AND(H3 >= 3, H3 < 4.8), 2, AND(H3 >= 4.8, H3 < 8.525), 3, AND(H3 >= 8.525, H3 <= 24.6), 4 ) )
C3: =IF(COUNTIF(Keeper!B:B,D3)>0,"x","") | D3: =Fantasypro!C3 | E3: =Fantasypro!D3 | F3: =Fantasypro!K3 | G3: =Fantasypro!H3 | H3: =Fantasypro!I3 | I3: =_xludf.IFS( F4 = "RB", _xludf.IFS( AND(H4 >= 0, H4 < 2.55), 1, AND(H4 >= 2.55, H4 < 4.7), 2, AND(H4 >= 4.7, H4 < 8.4), 3, AND(H4 >= 8.4, H4 <= 36), 4), F4 = "WR", _xludf.IFS( AND(H4 >= 0, H4 < 2.55), 1, AND(H4 >= 2.55, H4 < 4.2), 2, AND(H4 >= 4.2, H4 < 8.55), 3, AND(H4 >= 8.55, H4 <= 24.4), 4), F4 = "QB", _xludf.IFS( AND(H4 >= 0, H4 < 2.95), 1, AND(H4 >= 2.95, H4 < 5.4), 2, AND(H4 >= 5.4, H4 < 7.2), 3, AND(H4 >= 7.2, H4 <= 12.3), 4), F4 = "TE", _xludf.IFS( AND(H4 >= 0, H4 < 3), 1, AND(H4 >= 3, H4 < 4.8), 2, AND(H4 >= 4.8, H4 < 8.525), 3, AND(H4 >= 8.525, H4 <= 24.6), 4) )
C4: =IF(COUNTIF(Keeper!B:B,D4)>0,"x","") | D4: =Fantasypro!C4 | E4: =Fantasypro!D4 | F4: =Fantasypro!K4 | G4: =Fantasypro!H4 | H4: =Fantasypro!I4 | I4: =_xludf.IFS( F5 = "RB", _xludf.IFS( AND(H5 >= 0, H5 < 2.55), 1, AND(H5 >= 2.55, H5 < 4.7), 2, AND(H5 >= 4.7, H5 < 8.4), 3, AND(H5 >= 8.4, H5 <= 36), 4), F5 = "WR", _xludf.IFS( AND(H5 >= 0, H5 < 2.55), 1, AND(H5 >= 2.55, H5 < 4.2), 2, AND(H5 >= 4.2, H5 < 8.55), 3, AND(H5 >= 8.55, H5 <= 24.4), 4), F5 = "QB", _xludf.IFS( AND(H5 >= 0, H5 < 2.95), 1, AND(H5 >= 2.95, H5 < 5.4), 2, AND(H5 >= 5.4, H5 < 7.2), 3, AND(H5 >= 7.2, H5 <= 12.3), 4), F5 = "TE", _xludf.IFS( AND(H5 >= 0, H5 < 3), 1, AND(H5 >= 3, H5 < 4.8), 2, AND(H5 >= 4.8, H5 < 8.525), 3, AND(H5 >= 8.525, H5 <= 24.6), 4) )
C5: =IF(COUNTIF(Keeper!B:B,D5)>0,"x","") | D5: =Fantasypro!C5 | E5: =Fantasypro!D5 | F5: =Fantasypro!K5 | G5: =Fantasypro!H5 | H5: =Fantasypro!I5 | I5: =_xludf.IFS( F6 = "RB", _xludf.IFS( AND(H6 >= 0, H6 < 2.55), 1, AND(H6 >= 2.55, H6 < 4.7), 2, AND(H6 >= 4.7, H6 < 8.4), 3, AND(H6 >= 8.4, H6 <= 36), 4), F6 = "WR", _xludf.IFS( AND(H6 >= 0, H6 < 2.55), 1, AND(H6 >= 2.55, H6 < 4.2), 2, AND(H6 >= 4.2, H6 < 8.55), 3, AND(H6 >= 8.55, H6 <= 24.4), 4), F6 = "QB", _xludf.IFS( AND(H6 >= 0, H6 < 2.95), 1, AND(H6 >= 2.95, H6 < 5.4), 2, AND(H6 >= 5.4, H6 < 7.2), 3, AND(H6 >= 7.2, H6 <= 12.3), 4), F6 = "TE", _xludf.IFS( AND(H6 >= 0, H6 < 3), 1, AND(H6 >= 3, H6 < 4.8), 2, AND(H6 >= 4.8, H6 < 8.525), 3, AND(H6 >= 8.525, H6 <= 24.6), 4) )
C6: =IF(COUNTIF(Keeper!B:B,D6)>0,"x","") | D6: =Fantasypro!C6 | E6: =Fantasypro!D6 | F6: =Fantasypro!K6 | G6: =Fantasypro!H6 | H6: =Fantasypro!I6 | I6: =_xludf.IFS( F7 = "RB", _xludf.IFS( AND(H7 >= 0, H7 < 2.55), 1, AND(H7 >= 2.55, H7 < 4.7), 2, AND(H7 >= 4.7, H7 < 8.4), 3, AND(H7 >= 8.4, H7 <= 36), 4), F7 = "WR", _xludf.IFS( AND(H7 >= 0, H7 < 2.55), 1, AND(H7 >= 2.55, H7 < 4.2), 2, AND(H7 >= 4.2, H7 < 8.55), 3, AND(H7 >= 8.55, H7 <= 24.4), 4), F7 = "QB", _xludf.IFS( AND(H7 >= 0, H7 < 2.95), 1, AND(H7 >= 2.95, H7 < 5.4), 2, AND(H7 >= 5.4, H7 < 7.2), 3, AND(H7 >= 7.2, H7 <= 12.3), 4), F7 = "TE", _xludf.IFS( AND(H7 >= 0, H7 < 3), 1, AND(H7 >= 3, H7 < 4.8), 2, AND(H7 >= 4.8, H7 < 8.525), 3, AND(H7 >= 8.525, H7 <= 24.6), 4) )
C7: =IF(COUNTIF(Keeper!B:B,D7)>0,"x","") | D7: =Fantasypro!C7 | E7: =Fantasypro!D7 | F7: =Fantasypro!K7 | G7: =Fantasypro!H7 | H7: =Fantasypro!I7 | I7: =_xludf.IFS( F8 = "RB", _xludf.IFS( AND(H8 >= 0, H8 < 2.55), 1, AND(H8 >= 2.55, H8 < 4.7), 2, AND(H8 >= 4.7, H8 < 8.4), 3, AND(H8 >= 8.4, H8 <= 36), 4), F8 = "WR", _xludf.IFS( AND(H8 >= 0, H8 < 2.55), 1, AND(H8 >= 2.55, H8 < 4.2), 2, AND(H8 >= 4.2, H8 < 8.55), 3, AND(H8 >= 8.55, H8 <= 24.4), 4), F8 = "QB", _xludf.IFS( AND(H8 >= 0, H8 < 2.95), 1, AND(H8 >= 2.95, H8 < 5.4), 2, AND(H8 >= 5.4, H8 < 7.2), 3, AND(H8 >= 7.2, H8 <= 12.3), 4), F8 = "TE", _xludf.IFS( AND(H8 >= 0, H8 < 3), 1, AND(H8 >= 3, H8 < 4.8), 2, AND(H8 >= 4.8, H8 < 8.525), 3, AND(H8 >= 8.525, H8 <= 24.6), 4) )
C8: =IF(COUNTIF(Keeper!B:B,D8)>0,"x","") | D8: =Fantasypro!C8 | E8: =Fantasypro!D8 | F8: =Fantasypro!K8 | G8: =Fantasypro!H8 | H8: =Fantasypro!I8 | I8: =_xludf.IFS( F9 = "RB", _xludf.IFS( AND(H9 >= 0, H9 < 2.55), 1, AND(H9 >= 2.55, H9 < 4.7), 2, AND(H9 >= 4.7, H9 < 8.4), 3, AND(H9 >= 8.4, H9 <= 36), 4), F9 = "WR", _xludf.IFS( AND(H9 >= 0, H9 < 2.55), 1, AND(H9 >= 2.55, H9 < 4.2), 2, AND(H9 >= 4.2, H9 < 8.55), 3, AND(H9 >= 8.55, H9 <= 24.4), 4), F9 = "QB", _xludf.IFS( AND(H9 >= 0, H9 < 2.95), 1, AND(H9 >= 2.95, H9 < 5.4), 2, AND(H9 >= 5.4, H9 < 7.2), 3, AND(H9 >= 7.2, H9 <= 12.3), 4), F9 = "TE", _xludf.IFS( AND(H9 >= 0, H9 < 3), 1, AND(H9 >= 3, H9 < 4.8), 2, AND(H9 >= 4.8, H9 < 8.525), 3, AND(H9 >= 8.525, H9 <= 24.6), 4) )
C9: =IF(COUNTIF(Keeper!B:B,D9)>0,"x","") | D9: =Fantasypro!C9 | E9: =Fantasypro!D9 | F9: =Fantasypro!K9 | G9: =Fantasypro!H9 | H9: =Fantasypro!I9 | I9: =_xludf.IFS( F10 = "RB", _xludf.IFS( AND(H10 >= 0, H10 < 2.55), 1, AND(H10 >= 2.55, H10 < 4.7), 2, AND(H10 >= 4.7, H10 < 8.4), 3, AND(H10 >= 8.4, H10 <= 36), 4), F10 = "WR", _xludf.IFS( AND(H10 >= 0, H10 < 2.55), 1, AND(H10 >= 2.55, H10 < 4.2), 2, AND(H10 >= 4.2, H10 < 8.55), 3, AND(H10 >= 8.55, H10 <= 24.4), 4), F10 = "QB", _xludf.IFS( AND(H10 >= 0, H10 < 2.95), 1, AND(H10 >= 2.95, H10 < 5.4), 2, AND(H10 >= 5.4, H10 < 7.2), 3, AND(H10 >= 7.2, H10 <= 12.3), 4), F10 = "TE", _xludf.IFS( AND(H10 >= 0, H10 < 3), 1, AND(H10 >= 3, H10 < 4.8), 2, AND(H10 >= 4.8, H10 < 8.525), 3, AND(H10 >= 8.525, H10 <= 24.6), 4) )
C10: =IF(COUNTIF(Keeper!B:B,D10)>0,"x","") | D10: =Fantasypro!C10 | E10: =Fantasypro!D10 | F10: =Fantasypro!K10 | G10: =Fantasypro!H10 | H10: =Fantasypro!I10 | I10: =_xludf.IFS( F11 = "RB", _xludf.IFS( AND(H11 >= 0, H11 < 2.55), 1, AND(H11 >= 2.55, H11 < 4.7), 2, AND(H11 >= 4.7, H11 < 8.4), 3, AND(H11 >= 8.4, H11 <= 36), 4), F11 = "WR", _xludf.IFS( AND(H11 >= 0, H11 < 2.55), 1, AND(H11 >= 2.55, H11 < 4.2), 2, AND(H11 >= 4.2, H11 < 8.55), 3, AND(H11 >= 8.55, H11 <= 24.4), 4), F11 = "QB", _xludf.IFS( AND(H11 >= 0, H11 < 2.95), 1, AND(H11 >= 2.95, H11 < 5.4), 2, AND(H11 >= 5.4, H11 < 7.2), 3, AND(H11 >= 7.2, H11 <= 12.3), 4), F11 = "TE", _xludf.IFS( AND(H11 >= 0, H11 < 3), 1, AND(H11 >= 3, H11 < 4.8), 2, AND(H11 >= 4.8, H11 < 8.525), 3, AND(H11 >= 8.525, H11 <= 24.6), 4) )
C11: =IF(COUNTIF(Keeper!B:B,D11)>0,"x","") | D11: =Fantasypro!C11 | E11: =Fantasypro!D11 | F11: =Fantasypro!K11 | G11: =Fantasypro!H11 | H11: =Fantasypro!I11 | I11: =_xludf.IFS( F12 = "RB", _xludf.IFS( AND(H12 >= 0, H12 < 2.55), 1, AND(H12 >= 2.55, H12 < 4.7), 2, AND(H12 >= 4.7, H12 < 8.4), 3, AND(H12 >= 8.4, H12 <= 36), 4), F12 = "WR", _xludf.IFS( AND(H12 >= 0, H12 < 2.55), 1, AND(H12 >= 2.55, H12 < 4.2), 2, AND(H12 >= 4.2, H12 < 8.55), 3, AND(H12 >= 8.55, H12 <= 24.4), 4), F12 = "QB", _xludf.IFS( AND(H12 >= 0, H12 < 2.95), 1, AND(H12 >= 2.95, H12 < 5.4), 2, AND(H12 >= 5.4, H12 < 7.2), 3, AND(H12 >= 7.2, H12 <= 12.3), 4), F12 = "TE", _xludf.IFS( AND(H12 >= 0, H12 < 3), 1, AND(H12 >= 3, H12 < 4.8), 2, AND(H12 >= 4.8, H12 < 8.525), 3, AND(H12 >= 8.525, H12 <= 24.6), 4) )
C12: =IF(COUNTIF(Keeper!B:B,D12)>0,"x","") | D12: =Fantasypro!C12 | E12: =Fantasypro!D12 | F12: =Fantasypro!K12 | G12: =Fantasypro!H12 | H12: =Fantasypro!I12 | I12: =_xludf.IFS( F13 = "RB", _xludf.IFS( AND(H13 >= 0, H13 < 2.55), 1, AND(H13 >= 2.55, H13 < 4.7), 2, AND(H13 >= 4.7, H13 < 8.4), 3, AND(H13 >= 8.4, H13 <= 36), 4), F13 = "WR", _xludf.IFS( AND(H13 >= 0, H13 < 2.55), 1, AND(H13 >= 2.55, H13 < 4.2), 2, AND(H13 >= 4.2, H13 < 8.55), 3, AND(H13 >= 8.55, H13 <= 24.4), 4), F13 = "QB", _xludf.IFS( AND(H13 >= 0, H13 < 2.95), 1, AND(H13 >= 2.95, H13 < 5.4), 2, AND(H13 >= 5.4, H13 < 7.2), 3, AND(H13 >= 7.2, H13 <= 12.3), 4), F13 = "TE", _xludf.IFS( AND(H13 >= 0, H13 < 3), 1, AND(H13 >= 3, H13 < 4.8), 2, AND(H13 >= 4.8, H13 < 8.525), 3, AND(H13 >= 8.525, H13 <= 24.6), 4) )
C13: =IF(COUNTIF(Keeper!B:B,D13)>0,"x","") | D13: =Fantasypro!C13 | E13: =Fantasypro!D13 | F13: =Fantasypro!K13 | G13: =Fantasypro!H13 | H13: =Fantasypro!I13 | I13: =_xludf.IFS( F14 = "RB", _xludf.IFS( AND(H14 >= 0, H14 < 2.55), 1, AND(H14 >= 2.55, H14 < 4.7), 2, AND(H14 >= 4.7, H14 < 8.4), 3, AND(H14 >= 8.4, H14 <= 36), 4), F14 = "WR", _xludf.IFS( AND(H14 >= 0, H14 < 2.55), 1, AND(H14 >= 2.55, H14 < 4.2), 2, AND(H14 >= 4.2, H14 < 8.55), 3, AND(H14 >= 8.55, H14 <= 24.4), 4), F14 = "QB", _xludf.IFS( AND(H14 >= 0, H14 < 2.95), 1, AND(H14 >= 2.95, H14 < 5.4), 2, AND(H14 >= 5.4, H14 < 7.2), 3, AND(H14 >= 7.2, H14 <= 12.3), 4), F14 = "TE", _xludf.IFS( AND(H14 >= 0, H14 < 3), 1, AND(H14 >= 3, H14 < 4.8), 2, AND(H14 >= 4.8, H14 < 8.525), 3, AND(H14 >= 8.525, H14 <= 24.6), 4) )
C14: =IF(COUNTIF(Keeper!B:B,D14)>0,"x","") | D14: =Fantasypro!C14 | E14: =Fantasypro!D14 | F14: =Fantasypro!K14 | G14: =Fantasypro!H14 | H14: =Fantasypro!I14 | I14: =_xludf.IFS( F15 = "RB", _xludf.IFS( AND(H15 >= 0, H15 < 2.55), 1, AND(H15 >= 2.55, H15 < 4.7), 2, AND(H15 >= 4.7, H15 < 8.4), 3, AND(H15 >= 8.4, H15 <= 36), 4), F15 = "WR", _xludf.IFS( AND(H15 >= 0, H15 < 2.55), 1, AND(H15 >= 2.55, H15 < 4.2), 2, AND(H15 >= 4.2, H15 < 8.55), 3, AND(H15 >= 8.55, H15 <= 24.4), 4), F15 = "QB", _xludf.IFS( AND(H15 >= 0, H15 < 2.95), 1, AND(H15 >= 2.95, H15 < 5.4), 2, AND(H15 >= 5.4, H15 < 7.2), 3, AND(H15 >= 7.2, H15 <= 12.3), 4), F15 = "TE", _xludf.IFS( AND(H15 >= 0, H15 < 3), 1, AND(H15 >= 3, H15 < 4.8), 2, AND(H15 >= 4.8, H15 < 8.525), 3, AND(H15 >= 8.525, H15 <= 24.6), 4) )
... C25: =IF(COUNTIF(Keeper!B:B,D25)>0,"x","") | D25: =Fantasypro!C25 | E25: =Fantasypro!D25 | F25: =Fantasypro!K25 | G25: =Fantasypro!H25 | H25: =Fantasypro!I25 | I25: =_xludf.IFS( F26 = "RB", _xludf.IFS( AND(H26 >= 0, H26 < 2.55), 1, AND(H26 >= 2.55, H26 < 4.7), 2, AND(H26 >= 4.7, H26 < 8.4), 3, AND(H26 >= 8.4, H26 <= 36), 4), F26 = "WR", _xludf.IFS( AND(H26 >= 0, H26 < 2.55), 1, AND(H26 >= 2.55, H26 < 4.2), 2, AND(H26 >= 4.2, H26 < 8.55), 3, AND(H26 >= 8.55, H26 <= 24.4), 4), F26 = "QB", _xludf.IFS( AND(H26 >= 0, H26 < 2.95), 1, AND(H26 >= 2.95, H26 < 5.4), 2, AND(H26 >= 5.4, H26 < 7.2), 3, AND(H26 >= 7.2, H26 <= 12.3), 4), F26 = "TE", _xludf.IFS( AND(H26 >= 0, H26 < 3), 1, AND(H26 >= 3, H26 < 4.8), 2, AND(H26 >= 4.8, H26 < 8.525), 3, AND(H26 >= 8.525, H26 <= 24.6), 4) )
C26: x | D26: =Fantasypro!C26 | E26: =Fantasypro!D26 | F26: =Fantasypro!K26 | G26: =Fantasypro!H26 | H26: =Fantasypro!I26 | I26: =_xludf.IFS( F27 = "RB", _xludf.IFS( AND(H27 >= 0, H27 < 2.55), 1, AND(H27 >= 2.55, H27 < 4.7), 2, AND(H27 >= 4.7, H27 < 8.4), 3, AND(H27 >= 8.4, H27 <= 36), 4), F27 = "WR", _xludf.IFS( AND(H27 >= 0, H27 < 2.55), 1, AND(H27 >= 2.55, H27 < 4.2), 2, AND(H27 >= 4.2, H27 < 8.55), 3, AND(H27 >= 8.55, H27 <= 24.4), 4), F27 = "QB", _xludf.IFS( AND(H27 >= 0, H27 < 2.95), 1, AND(H27 >= 2.95, H27 < 5.4), 2, AND(H27 >= 5.4, H27 < 7.2), 3, AND(H27 >= 7.2, H27 <= 12.3), 4), F27 = "TE", _xludf.IFS( AND(H27 >= 0, H27 < 3), 1, AND(H27 >= 3, H27 < 4.8), 2, AND(H27 >= 4.8, H27 < 8.525), 3, AND(H27 >= 8.525, H27 <= 24.6), 4) )
C27: =IF(COUNTIF(Keeper!B:B,D27)>0,"x","") | D27: =Fantasypro!C27 | E27: =Fantasypro!D27 | F27: =Fantasypro!K27 | G27: =Fantasypro!H27 | H27: =Fantasypro!I27 | I27: 2
C28: =IF(COUNTIF(Keeper!B:B,D28)>0,"x","") | D28: =#REF! | E28: =#REF! | F28: =#REF! | G28: =#REF! | H28: =#REF! | I28: =_xludf.IFS( F29 = "RB", _xludf.IFS( AND(H29 >= 0, H29 < 2.55), 1, AND(H29 >= 2.55, H29 < 4.7), 2, AND(H29 >= 4.7, H29 < 8.4), 3, AND(H29 >= 8.4, H29 <= 36), 4 ), F29 = "WR", _xludf.IFS( AND(H29 >= 0, H29 < 2.55), 1, AND(H29 >= 2.55, H29 < 4.2), 2, AND(H29 >= 4.2, H29 < 8.55), 3, AND(H29 >= 8.55, H29 <= 24.4), 4 ), F29 = "QB", _xludf.IFS( AND(H29 >= 0, H29 < 2.95), 1, AND(H29 >= 2.95, H29 < 5.4), 2, AND(H29 >= 5.4, H29 < 7.2), 3, AND(H29 >= 7.2, H29 <= 12.3), 4 ), F29 = "TE", _xludf.IFS( AND(H29 >= 0, H29 < 3), 1, AND(H29 >= 3, H29 < 4.8), 2, AND(H29 >= 4.8, H29 < 8.525), 3, AND(H29 >= 8.525, H29 <= 24.6), 4 ) )
C29: =IF(COUNTIF(Keeper!B:B,D29)>0,"x","") | D29: =#REF! | E29: =#REF! | F29: =#REF! | G29: =#REF! | H29: =#REF! | I29: =_xludf.IFS( F30 = "RB", _xludf.IFS( AND(H30 >= 0, H30 < 2.55), 1, AND(H30 >= 2.55, H30 < 4.7), 2, AND(H30 >= 4.7, H30 < 8.4), 3, AND(H30 >= 8.4, H30 <= 36), 4), F30 = "WR", _xludf.IFS( AND(H30 >= 0, H30 < 2.55), 1, AND(H30 >= 2.55, H30 < 4.2), 2, AND(H30 >= 4.2, H30 < 8.55), 3, AND(H30 >= 8.55, H30 <= 24.4), 4), F30 = "QB", _xludf.IFS( AND(H30 >= 0, H30 < 2.95), 1, AND(H30 >= 2.95, H30 < 5.4), 2, AND(H30 >= 5.4, H30 < 7.2), 3, AND(H30 >= 7.2, H30 <= 12.3), 4), F30 = "TE", _xludf.IFS( AND(H30 >= 0, H30 < 3), 1, AND(H30 >= 3, H30 < 4.8), 2, AND(H30 >= 4.8, H30 < 8.525), 3, AND(H30 >= 8.525, H30 <= 24.6), 4) )
